Workbook
Name Slicer_Cap: #N/A
Name Slicer_Cap1: #N/A
Name Slicer_Loại_HĐ: #N/A
Name Slicer_PhongBan: #N/A
Name Slicer_PhongBan1: #N/A
Name Slicer_Tháng: #N/A
Name Slicer_Tháng1: #N/A
Name Slicer_Tháng2: #N/A
Name Slicer_Tháng3: #N/A
Name Slicer_Tháng4: #N/A

Sheet Dashboard 
J2: BÁO CÁO VẬN HÀNH THÁNG
J3: Tháng 9/ 2026
B4: PHẦN 1. CHỈ TIÊU SĨ SỐ HỌC SINH
B6: 1. Mức độ hoàn thành chỉ tiêu tuyển sinh | E6: 2. Tỷ lệ hoàn thành mục tiêu tuyển sinh theo cơ sở
B8: Chỉ tiêu học sinh | C8: ='1. Sĩ số học sinh'!J28 -> 2873
B9: Học sinh thực tế | C9: ='1. Sĩ số học sinh'!L28 -> 2625
B10: % đạt mục tiêu | C10: =C9/C8 -> 0.91367908
B11: Học sinh còn thiếu | C11: =C8-C9 -> 248
B13: 3. So sánh chỉ tiêu và thực tế đạt được, tăng giảm trong tháng
B29: 4. Biến động sĩ số học sinh rút hồ sơ lũy kế tháng theo khối/ cơ sở
B57: PHẦN 2. CÂU LẠC BỘ NGOẠI KHÓA
B58: Số liệu câu lạc bộ ngoại khóa trong tháng (khai giảng tháng 9/2026) | F58: Tỷ lệ hoàn thành chỉ tiêu CLB
F59: Cơ sở/ Khối lớp | H59: % chỉ tiêu
F60: Mầm non Biên Hòa | H60: ='2. Câu lạc bộ'!N2 -> 0.64166667
F61: Mầm non Long Khánh | H61: ='2. Câu lạc bộ'!N3 -> 0.93333333
F62: Tiểu học | H62: ='2. Câu lạc bộ'!N4 -> 1.1766667
F63: Trung học | H63: ='2. Câu lạc bộ'!N5 -> 0.64
B65: - Mầm non Biên Hòa chỉ đạt 64% chỉ tiêu. Năm học tiếp theo cần cải thiện công tác dự báo và đặt chỉ tiêu/ số lớp phù hợp với số lượng học sinh khối Chồi Lá. Đồng thời cũng cải tiến công tác truyền thông, tổ chức giảng dạy để chương trình hấp dẫn, phù hợp với nhu cầu của PH, HS (cụ thể: Giảm nhu cầu lớp vẽ vì đã có trong tiết chính khóa). Câu lạc bộ Mầm non Biên Hòa thu hút đông học sinh gồm Tiếng Anh Kịch nghệ (thầy Abhi dạy) và Aerobic - Mầm non Long Khánh gần cán đích mục tiêu tuyển sinh Câu lạc bộ với 93% học sinh. Một số CLB có số học sinh vượt 15 HS/ lớp gồm Tiền Tiểu học, Nhảy Hiện đại, Tiếng Anh. Đối với 2 trường mầm non, Câu lạc bộ Nhạc kịch là điểm mới của năm học này đã thu hút được lượng học sinh tham dự vượt kỳ vọng ban đầu (do phí thu CLB này cao gấp đôi so với các CLB khác). Tiểu học đang vượt chỉ tiêu CLB Ngoại khóa . Hầu hết các CLB đều có sĩ số HS cao, tăng hơn 30 học sinh so với cùng kỳ năm trước. Không mở được lớp Khoa học vui do số lượng học sinh đăng ký không đủ chỉ tiêu mở lớp Trung học 2 CLB không mở được gồm Lập trình Game và Cờ Vua, CLB có sĩ số thấp < 10 HS gồm Advanced Robotics, Ẩm thực, Bóng Chuyền, Bóng rổ. Năm học 2026 - 2027 được sự tạo điều kiện của BGH, các CLB đã được sắp xếp sau giờ học vào tiết cuối nên số lượng CLB và học sinh tham dự đông hơn so với năm trước (tổ chức vào thứ 7).
B66: Số liệu học sinh theo môn học CLB
B103: PHẦN 3. TÌNH HÌNH SỨC KHỎE HỌC SINH
B108: 1. Bệnh phổ biến trong tháng cấp học mầm non
B109: Tháng 9, tổng cộng cơ sở 2 có 30 ca bị tay chân miệng tập trung ở lớp nhà trẻ (Kitty và Bee). Cần có giải pháp hiệu quả để dự phòng và ngăn ngừa dịch bệnh.
B119: 2. Bệnh phổ biến trong tháng cấp Tiểu học
B120: Bệnh lý chủ đạo: Tập trung vào nhóm Tổng hợp (đau đầu, đau bụng hoặc mệt chưa rõ nguyên nhân) với 135 lượt khám, Tai mũi họng 84 lượt và 53 ca sốt. Cuối tháng 9, cấp tiểu học ghi nhận nhiều ca bị Cúm A cần theo dõi và khử khuẩn tại khối 4 và 5.
B131: 3. Bệnh phổ biến trong tháng cấp THCS
B132: Bệnh lý chủ đạo: Tập trung vào các bệnh tổng hợp (đau đầu, đau bụng và mệt không rõ nguyên nhân), tai mũi họng và chấn thương do chơi thể thao (hội thao chào mừng 15 năm thành lập trường)
B143: 4. Bệnh phổ biến trong tháng cấp THPT
B144: Bệnh lý chủ đạo: Viêm họng, Thống Kinh, Bệnh tổng hợp không rõ nguyên nhân
B154: 5. Công tác truyền thông
... B260: Lắp đặt mới
B263: Báo lỗi xử lý | C263: Đa phần vẫn tập trung vào máy lạnh. Bộ phận Cơ sở vật chất đã đề xuất mua 20 máy lạnh mới thay thế tại khu B trong tháng 10.
B274: Hạng mục bảo trì trong tháng
B275: Bảo trì phòng học khu B, C | D275: Bảo trì thang máy mầm non Long Khánh
B276: Bảo trì camera định kỳ mầm non | D276: Bảo trì máy lọc nước Coway
B277: Bảo trì phòng máy tính khu E và C
B278: 2. Ăn sáng & Xe đưa rước
B279: Tiếp tục thúc đẩy và chăm sóc học sinh ăn sáng, xe đưa rước để duy trì sĩ số và doanh thu (Tháng 9 ghi nhận sụt giảm ở cả 2 dịch vụ)
C280: Tháng 8 | D280: Tháng 9 | E280: Tháng 10 | F280: Tháng 11 | G280: Tháng 12 | H280: Tháng 1 | I280: Tháng 3
B281: Xe đưa rước | C281: 329 | D281: 315 | E281: 316
B282: Tăng/ (giảm) | C282: -1 | D282: =D281-C281 -> -14 | E282: =E281-D281 -> 1
...

Sheet 1. Sĩ số học sinh
K1: Số lượng HS thực tế
A2: Cơ sở/ Khối lớp | B2: Số lớp 22 – 23 | C2: Số lớp 23 - 24 | D2: Số lớp 24 - 25 Mục tiêu | E2: Số lớp 24 - 25 Thực tế | F2: Số học sinh 22 - 23 | G2: Số học sinh 23 - 24 | H2: Số học sinh 24 -25 | I2: Số học sinh 25 -26 | J2: Số học sinh chỉ tiêu năm 26 - 27 | K2: 8/2026 | L2: 9/2026 | M2: 10/2026 | N2: 11/2026 | O2: 12/2026 | P2: 1/2027 | Q2: 2/2027 | R2: 3/2027 | S2: 4/2027 | T2: 5/2027 | U2: 6/2027 | V2: 7/2026 | W2: Số HS (thiếu)/ Vượt chỉ tiêu | X2: % Thực tế và chỉ tiêu tháng 8 | Y2: % Thực tế và chỉ tiêu Tháng 9 | Z2: % Thực tế và chỉ tiêu Tháng 10 | AA2: % Thực tế và chỉ tiêu Tháng 11 | AB2: % Thực tế và chỉ tiêu Tháng 12 | AC2: % Thực tế và chỉ tiêu Tháng 1 | AD2: % Thực tế và chỉ tiêu Tháng 2 | AE2: % Thực tế và chỉ tiêu Tháng 3 | AF2: % Thực tế và chỉ tiêu Tháng4 | AG2: % Thực tế và chỉ tiêu Tháng 5 | AJ2: Tăng/ (Giảm) so với tháng trước
A3: MN Biên Hòa | B3: 19 | C3: 20 | D3: =SUM(D4:D7) -> 21 | E3: =SUM(E4:E7) -> 20 | F3: 418 | G3: 427 | J3: =SUM(J4:J7) -> 406 | K3: =SUM(K4:K7) -> 353 | L3: =SUM(L4:L7) -> 357 | M3: =SUM(M4:M7) -> 0 | N3: =SUM(N4:N7) -> 0 | O3: =SUM(O4:O7) -> 0 | P3: =SUM(P4:P7) -> 0 | Q3: =SUM(Q4:Q7) -> 0 | ... T3: =SUM(T4:T7) -> 0 | W3: =T3-J3 -> -406 | X3: =K3/J3 -> 0.86945813 | Y3: =L3/J3 -> 0.87931034 | Z3: =M3/J3 -> 0 | AA3: =N3/$J3 -> 0 | AB3: =O3/$J3 -> 0 | AC3: =P3/$J3 -> 0 | AD3: =Q3/$J3 -> 0 | AE3: =R3/$J3 -> 0 | AF3: =S3/$J3 -> 0 | AG3: =T3/$J3 -> 0 | AJ3: =P3-O3 -> 0
A4: Nhà trẻ | B4: 3 | C4: 4 | D4: 4 | E4: 4 | F4: 47 | G4: 64 | J4: =24+80 -> 104 | K4: =14+75 -> 89 | L4: =15+75 -> 90 | W4: =T4-J4 -> -104 | X4: =K4/J4 -> 0.85576923 | Y4: =L4/J4 -> 0.86538462 | Z4: =M4/J4 -> 0 | AA4: =N4/$J4 -> 0 | AB4: =O4/$J4 -> 0 | AC4: =P4/$J4 -> 0 | AD4: =Q4/$J4 -> 0 | AE4: =R4/$J4 -> 0 | AF4: =S4/$J4 -> 0 | AG4: =T4/$J4 -> 0 | AJ4: =R4-Q4 -> 0
A5: Mầm | B5: 5 | C5: 5 | D5: 6 | E5: 5 | F5: 99 | G5: 100 | J5: 100 | K5: 77 | L5: 80 | W5: =T5-J5 -> -100 | X5: =K5/J5 -> 0.77 | Y5: =L5/J5 -> 0.8 | Z5: =M5/J5 -> 0 | AA5: =N5/$J5 -> 0 | AB5: =O5/$J5 -> 0 | AC5: =P5/$J5 -> 0 | AD5: =Q5/$J5 -> 0 | AE5: =R5/$J5 -> 0 | AF5: =S5/$J5 -> 0 | AG5: =T5/$J5 -> 0 | AJ5: =R5-Q5 -> 0
A6: Chồi | B6: 5 | C6: 6 | D6: 5 | E6: 5 | F6: 120 | G6: 131 | J6: 72 | K6: 67 | L6: 67 | W6: =T6-J6 -> -72 | X6: =K6/J6 -> 0.93055556 | Y6: =L6/J6 -> 0.93055556 | Z6: =M6/J6 -> 0 | AA6: =N6/$J6 -> 0 | AB6: =O6/$J6 -> 0 | AC6: =P6/$J6 -> 0 | AD6: =Q6/$J6 -> 0 | AE6: =R6/$J6 -> 0 | AF6: =S6/$J6 -> 0 | AG6: =T6/$J6 -> 0 | AJ6: =R6-Q6 -> 0
A7: Lá | B7: 6 | C7: 5 | D7: 6 | E7: 6 | F7: 152 | G7: 132 | J7: 130 | K7: 120 | L7: 120 | W7: =T7-J7 -> -130 | X7: =K7/J7 -> 0.92307692 | Y7: =L7/J7 -> 0.92307692 | Z7: =M7/J7 -> 0 | AA7: =N7/$J7 -> 0 | AB7: =O7/$J7 -> 0 | AC7: =P7/$J7 -> 0 | AD7: =Q7/$J7 -> 0 | AE7: =R7/$J7 -> 0 | AF7: =S7/$J7 -> 0 | AG7: =T7/$J7 -> 0 | AJ7: =R7-Q7 -> 0
A8: MN Long Khánh | B8: 9 | C8: 9 | D8: =SUM(D9:D12) -> 9 | E8: =SUM(E9:E12) -> 9 | F8: 176 | G8: 159 | J8: =SUM(J9:J12) -> 166 | K8: =SUM(K9:K12) -> 123 | L8: =SUM(L9:L12) -> 129 | M8: =SUM(M9:M12) -> 0 | N8: =SUM(N9:N12) -> 0 | O8: =SUM(O9:O12) -> 0 | P8: =SUM(P9:P12) -> 0 | Q8: =SUM(Q9:Q12) -> 0 | ... T8: =SUM(T9:T12) -> 0 | W8: =T8-J8 -> -166 | X8: =K8/J8 -> 0.74096386 | Y8: =L8/J8 -> 0.77710843 | Z8: =M8/J8 -> 0 | AA8: =N8/$J8 -> 0 | AB8: =O8/$J8 -> 0 | AC8: =P8/$J8 -> 0 | AD8: =Q8/$J8 -> 0 | AE8: =R8/$J8 -> 0 | AF8: =S8/$J8 -> 0 | AG8: =T8/$J8 -> 0 | AJ8: =P8-O8 -> 0
A9: Nhà trẻ | B9: 3 | C9: 2 | D9: 2 | E9: 2 | F9: 36 | G9: 35 | J9: 76 | K9: 48 | L9: =5+46 -> 51 | W9: =T9-J9 -> -76 | X9: =K9/J9 -> 0.63157895 | Y9: =L9/J9 -> 0.67105263 | Z9: =M9/J9 -> 0 | AA9: =N9/$J9 -> 0 | AB9: =O9/$J9 -> 0 | AC9: =P9/$J9 -> 0 | AD9: =Q9/$J9 -> 0 | AE9: =R9/$J9 -> 0 | AF9: =S9/$J9 -> 0 | AG9: =T9/$J9 -> 0 | AJ9: =R9-Q9 -> 0
A10: Mầm | B10: 2 | C10: 2 | D10: 2 | E10: 2 | F10: 64 | G10: 40 | J10: 40 | K10: 33 | L10: 34 | W10: =T10-J10 -> -40 | X10: =K10/J10 -> 0.825 | Y10: =L10/J10 -> 0.85 | Z10: =M10/J10 -> 0 | AA10: =N10/$J10 -> 0 | AB10: =O10/$J10 -> 0 | AC10: =P10/$J10 -> 0 | AD10: =Q10/$J10 -> 0 | AE10: =R10/$J10 -> 0 | AF10: =S10/$J10 -> 0 | AG10: =T10/$J10 -> 0 | AJ10: =R10-Q10 -> 0
A11: Chồi | B11: 2 | C11: 3 | D11: 3 | E11: 3 | F11: 38 | G11: 50 | J11: 24 | K11: 22 | L11: 23 | W11: =T11-J11 -> -24 | X11: =K11/J11 -> 0.91666667 | Y11: =L11/J11 -> 0.95833333 | Z11: =M11/J11 -> 0 | AA11: =N11/$J11 -> 0 | AB11: =O11/$J11 -> 0 | AC11: =P11/$J11 -> 0 | AD11: =Q11/$J11 -> 0 | AE11: =R11/$J11 -> 0 | AF11: =S11/$J11 -> 0 | AG11: =T11/$J11 -> 0 | AJ11: =R11-Q11 -> 0
A12: Lá | B12: 2 | C12: 2 | D12: 2 | E12: 2 | F12: 38 | G12: 34 | J12: 26 | K12: 20 | L12: 21 | W12: =T12-J12 -> -26 | X12: =K12/J12 -> 0.76923077 | Y12: =L12/J12 -> 0.80769231 | Z12: =M12/J12 -> 0 | AA12: =N12/$J12 -> 0 | AB12: =O12/$J12 -> 0 | AC12: =P12/$J12 -> 0 | AD12: =Q12/$J12 -> 0 | AE12: =R12/$J12 -> 0 | AF12: =S12/$J12 -> 0 | AG12: =T12/$J12 -> 0 | AJ12: =R12-Q12 -> 0
A13: Tiểu học | B13: 37 | C13: 39 | D13: =SUM(D14:D18) -> 39 | E13: =SUM(E14:E18) -> 38 | F13: 1006 | G13: 1017 | J13: =SUM(J14:J18) -> 980 | K13: =SUM(K14:K18) -> 897 | L13: =SUM(L14:L18) -> 897 | M13: =SUM(M14:M18) -> 0 | N13: =SUM(N14:N18) -> 0 | O13: =SUM(O14:O18) -> 0 | P13: =SUM(P14:P18) -> 0 | Q13: =SUM(Q14:Q18) -> 0 | ... T13: =SUM(T14:T18) -> 0 | W13: =T13-J13 -> -980 | X13: =K13/J13 -> 0.91530612 | Y13: =L13/J13 -> 0.91530612 | Z13: =M13/J13 -> 0 | AA13: =N13/$J13 -> 0 | AB13: =O13/$J13 -> 0 | AC13: =P13/$J13 -> 0 | AD13: =Q13/$J13 -> 0 | AE13: =R13/$J13 -> 0 | AF13: =S13/$J13 -> 0 | AG13: =T13/$J13 -> 0 | AJ13: =P13-O13 -> 0
A14: Khối 1 | B14: 9 | C14: 9 | D14: 8 | E14: 7 | F14: 244 | G14: 228 | J14: 196 | K14: 170 | L14: 171 | W14: =T14-J14 -> -196 | X14: =K14/J14 -> 0.86734694 | Y14: =L14/J14 -> 0.87244898 | Z14: =M14/J14 -> 0 | AA14: =N14/$J14 -> 0 | AB14: =O14/$J14 -> 0 | AC14: =P14/$J14 -> 0 | AD14: =Q14/$J14 -> 0 | AE14: =R14/$J14 -> 0 | AF14: =S14/$J14 -> 0 | AG14: =T14/$J14 -> 0 | AJ14: =R14-Q14 -> 0
A15: Khối 2 | B15: 7 | C15: 9 | D15: 8 | E15: 8 | F15: 195 | G15: 231 | J15: 196 | K15: 170 | L15: 171 | W15: =T15-J15 -> -196 | X15: =K15/J15 -> 0.86734694 | Y15: =L15/J15 -> 0.87244898 | Z15: =M15/J15 -> 0 | AA15: =N15/$J15 -> 0 | AB15: =O15/$J15 -> 0 | AC15: =P15/$J15 -> 0 | AD15: =Q15/$J15 -> 0 | AE15: =R15/$J15 -> 0 | AF15: =S15/$J15 -> 0 | AG15: =T15/$J15 -> 0 | AJ15: =R15-Q15 -> 0
A16: Khối 3 | B16: 7 | C16: 7 | D16: 9 | E16: 9 | F16: 194 | G16: 192 | J16: 196 | K16: 172 | L16: 171 | W16: =T16-J16 -> -196 | X16: =K16/J16 -> 0.87755102 | Y16: =L16/J16 -> 0.87244898 | Z16: =M16/J16 -> 0 | AA16: =N16/$J16 -> 0 | AB16: =O16/$J16 -> 0 | AC16: =P16/$J16 -> 0 | AD16: =Q16/$J16 -> 0 | AE16: =R16/$J16 -> 0 | AF16: =S16/$J16 -> 0 | AG16: =T16/$J16 -> 0 | AJ16: =R16-Q16 -> 0
A17: Khối 4 | B17: 7 | C17: 7 | D17: 7 | E17: 7 | F17: 177 | G17: 191 | J17: 196 | K17: 192 | L17: 192 | W17: =T17-J17 -> -196 | X17: =K17/J17 -> 0.97959184 | Y17: =L17/J17 -> 0.97959184 | Z17: =M17/J17 -> 0 | AA17: =N17/$J17 -> 0 | AB17: =O17/$J17 -> 0 | AC17: =P17/$J17 -> 0 | AD17: =Q17/$J17 -> 0 | AE17: =R17/$J17 -> 0 | AF17: =S17/$J17 -> 0 | AG17: =T17/$J17 -> 0 | AJ17: =R17-Q17 -> 0
A18: Khối 5 | B18: 7 | C18: 7 | D18: 7 | E18: 7 | F18: 196 | G18: 175 | J18: 196 | K18: 193 | L18: 192 | W18: =T18-J18 -> -196 | X18: =K18/J18 -> 0.98469388 | Y18: =L18/J18 -> 0.97959184 | Z18: =M18/J18 -> 0 | AA18: =N18/$J18 -> 0 | AB18: =O18/$J18 -> 0 | AC18: =P18/$J18 -> 0 | AD18: =Q18/$J18 -> 0 | AE18: =R18/$J18 -> 0 | AF18: =S18/$J18 -> 0 | AG18: =T18/$J18 -> 0 | AJ18: =R18-Q18 -> 0
A19: THCS | B19: 28 | C19: 27 | D19: =SUM(D20:D23) -> 29 | E19: =SUM(E20:E23) -> 28 | F19: 719 | G19: 757 | J19: =SUM(J20:J23) -> 841 | K19: =SUM(K20:K23) -> 799 | L19: =SUM(L20:L23) -> 799 | M19: =SUM(M20:M23) -> 0 | N19: =SUM(N20:N23) -> 0 | O19: =SUM(O20:O23) -> 0 | P19: =SUM(P20:P23) -> 0 | Q19: =SUM(Q20:Q23) -> 0 | ... T19: =SUM(T20:T23) -> 0 | W19: =T19-J19 -> -841 | X19: =K19/J19 -> 0.95005945 | Y19: =L19/J19 -> 0.95005945 | Z19: =M19/J19 -> 0 | AA19: =N19/$J19 -> 0 | AB19: =O19/$J19 -> 0 | AC19: =P19/$J19 -> 0 | AD19: =Q19/$J19 -> 0 | AE19: =R19/$J19 -> 0 | AF19: =S19/$J19 -> 0 | AG19: =T19/$J19 -> 0 | AJ19: =P19-O19 -> 0
A20: Khối 6 | B20: 7 | C20: 8 | D20: 8 | E20: 7 | F20: 196 | G20: 227 | J20: 232 | K20: 216 | L20: 217 | W20: =T20-J20 -> -232 | X20: =K20/J20 -> 0.93103448 | Y20: =L20/J20 -> 0.93534483 | Z20: =M20/J20 -> 0 | AA20: =N20/$J20 -> 0 | AB20: =O20/$J20 -> 0 | AC20: =P20/$J20 -> 0 | AD20: =Q20/$J20 -> 0 | AE20: =R20/$J20 -> 0 | AF20: =S20/$J20 -> 0 | AG20: =T20/$J20 -> 0 | AJ20: =R20-Q20 -> 0
A21: Khối 7 | B21: 7 | C21: 7 | D21: 8 | E21: 8 | F21: 170 | G21: 197 | J21: 232 | K21: 209 | L21: 208 | W21: =T21-J21 -> -232 | X21: =K21/J21 -> 0.90086207 | Y21: =L21/J21 -> 0.89655172 | Z21: =M21/J21 -> 0 | AA21: =N21/$J21 -> 0 | AB21: =O21/$J21 -> 0 | AC21: =P21/$J21 -> 0 | AD21: =Q21/$J21 -> 0 | AE21: =R21/$J21 -> 0 | AF21: =S21/$J21 -> 0 | AG21: =T21/$J21 -> 0 | AJ21: =R21-Q21 -> 0
A22: Khối 8 | B22: 7 | C22: 6 | D22: 7 | E22: 7 | F22: 178 | G22: 155 | J22: 174 | K22: 167 | L22: 167 | W22: =T22-J22 -> -174 | X22: =K22/J22 -> 0.95977011 | Y22: =L22/J22 -> 0.95977011 | Z22: =M22/J22 -> 0 | AA22: =N22/$J22 -> 0 | AB22: =O22/$J22 -> 0 | AC22: =P22/$J22 -> 0 | AD22: =Q22/$J22 -> 0 | AE22: =R22/$J22 -> 0 | AF22: =S22/$J22 -> 0 | AG22: =T22/$J22 -> 0 | AJ22: =R22-Q22 -> 0
A23: Khối 9 | B23: 7 | C23: 6 | D23: 6 | E23: 6 | F23: 175 | G23: 178 | J23: 203 | K23: 207 | L23: 207 | W23: =T23-J23 -> -203 | X23: =K23/J23 -> 1.0197044 | Y23: =L23/J23 -> 1.0197044 | Z23: =M23/J23 -> 0 | AA23: =N23/$J23 -> 0 | AB23: =O23/$J23 -> 0 | AC23: =P23/$J23 -> 0 | AD23: =Q23/$J23 -> 0 | AE23: =R23/$J23 -> 0 | AF23: =S23/$J23 -> 0 | AG23: =T23/$J23 -> 0 | AJ23: =R23-Q23 -> 0
A24: THPT | B24: 18 | C24: 18 | D24: =SUM(D25:D27) -> 18 | E24: =SUM(E25:E27) -> 16 | F24: 512 | G24: 492 | J24: =SUM(J25:J27) -> 480 | K24: =SUM(K25:K27) -> 444 | L24: =SUM(L25:L27) -> 443 | M24: =SUM(M25:M27) -> 0 | N24: =SUM(N25:N27) -> 0 | O24: =SUM(O25:O27) -> 0 | P24: =SUM(P25:P27) -> 0 | Q24: =SUM(Q25:Q27) -> 0 | ... T24: =SUM(T25:T27) -> 0 | W24: =T24-J24 -> -480 | X24: =K24/J24 -> 0.925 | Y24: =L24/J24 -> 0.92291667 | Z24: =M24/J24 -> 0 | AA24: =N24/$J24 -> 0 | AB24: =O24/$J24 -> 0 | AC24: =P24/$J24 -> 0 | AD24: =Q24/$J24 -> 0 | AE24: =R24/$J24 -> 0 | AF24: =S24/$J24 -> 0 | AG24: =T24/$J24 -> 0 | AJ24: =P24-O24 -> 0
A25: Khối 10 | B25: 6 | C25: 6 | D25: 6 | E25: 4 | F25: 171 | G25: 169 | J25: 180 | K25: 185 | L25: 185 | W25: =T25-J25 -> -180 | X25: =K25/J25 -> 1.0277778 | Y25: =L25/J25 -> 1.0277778 | Z25: =M25/J25 -> 0 | AA25: =N25/$J25 -> 0 | AB25: =O25/$J25 -> 0 | AC25: =P25/$J25 -> 0 | AD25: =Q25/$J25 -> 0 | AE25: =R25/$J25 -> 0 | AF25: =S25/$J25 -> 0 | AG25: =T25/$J25 -> 0 | AJ25: =R25-Q25 -> 0
A26: Khối 11 | B26: 6 | C26: 6 | D26: 6 | E26: 6 | F26: 169 | G26: 161 | J26: 150 | K26: 126 | L26: 125 | W26: =T26-J26 -> -150 | X26: =K26/J26 -> 0.84 | Y26: =L26/J26 -> 0.83333333 | Z26: =M26/J26 -> 0 | AA26: =N26/$J26 -> 0 | AB26: =O26/$J26 -> 0 | AC26: =P26/$J26 -> 0 | AD26: =Q26/$J26 -> 0 | AE26: =R26/$J26 -> 0 | AF26: =S26/$J26 -> 0 | AG26: =T26/$J26 -> 0 | AJ26: =R26-Q26 -> 0
A27: Khối 12 | B27: 6 | C27: 6 | D27: 6 | E27: 6 | F27: 172 | G27: 162 | J27: 150 | K27: 133 | L27: 133 | W27: =T27-J27 -> -150 | X27: =K27/J27 -> 0.88666667 | Y27: =L27/J27 -> 0.88666667 | Z27: =M27/J27 -> 0 | AA27: =N27/$J27 -> 0 | AB27: =O27/$J27 -> 0 | AC27: =P27/$J27 -> 0 | AD27: =Q27/$J27 -> 0 | AE27: =R27/$J27 -> 0 | AF27: =S27/$J27 -> 0 | AG27: =T27/$J27 -> 0 | AJ27: =R27-Q27 -> 0
A28: Total | B28: 111 | C28: 113 | D28: =D24+D19+D13+D8+D3 -> 116 | E28: =E24+E19+E13+E8+E3 -> 111 | F28: =F24+F19+F13+F8+F3 -> 2831 | G28: =G24+G19+G13+G8+G3 -> 2852 | J28: =J24+J19+J13+J8+J3 -> 2873 | K28: =K24+K19+K13+K8+K3 -> 2616 | L28: =L24+L19+L13+L8+L3 -> 2625 | M28: =M24+M19+M13+M8+M3 -> 0 | N28: =N24+N19+N13+N8+N3 -> 0 | O28: =O24+O19+O13+O8+O3 -> 0 | P28: =P24+P19+P13+P8+P3 -> 0 | Q28: =Q24+Q19+Q13+Q8+Q3 -> 0 | ... T28: =T24+T19+T13+T8+T3 -> 0 | W28: =T28-J28 -> -2873 | X28: =K28/J28 -> 0.91054647 | Y28: =L28/J28 -> 0.91367908 | Z28: =M28/J28 -> 0 | AA28: =N28/$J28 -> 0 | AB28: =O28/$J28 -> 0 | AC28: =P28/$J28 -> 0 | AD28: =Q28/$J28 -> 0 | AE28: =R28/$J28 -> 0 | AF28: =S28/$J28 -> 0 | AG28: =T28/$J28 -> 0 | AJ28: =P28-O28 -> 0
A31: Khối/ Tháng | J31: Lũy kế học sinh chuyển đi | K31: =K2 -> 8/2026 | L31: =L2 -> 9/2026 | M31: =M2 -> 10/2026 | N31: =N2 -> 11/2026 | O31: =O2 -> 12/2026 | P31: =P2 -> 1/2027 | Q31: =Q2 -> 2/2027 | R31: =R2 -> 3/2027 | ... T31: =T2 -> 5/2027 | U31: 6/2026 | V31: 7/2026 | W31: Khối/ Tháng | X31: Lũy kế học sinh chuyển đến | Y31: =K31 -> 8/2026 | Z31: =L31 -> 9/2026 | AA31: =M31 -> 10/2026 | AB31: =N31 -> 11/2026 | AC31: =O31 -> 12/2026 | AD31: =P31 -> 1/2027 | AE31: =Q31 -> 2/2027 | AF31: =R31 -> 3/2027 | ... AJ31: =V31 -> 7/2026 | AK31: Khối/ Tháng | AL31: Lũy kế HS đến - đi | AM31: =Y31 -> 8/2026 | AN31: =Z31 -> 9/2026 | AO31: =AA31 -> 10/2026 | AP31: =AB31 -> 11/2026 | AQ31: =AC31 -> 12/2026 | AR31: =AD31 -> 1/2027 | AS31: =AE31 -> 2/2027 | AT31: =AF31 -> 3/2027 | ... AX31: =AJ31 -> 7/2026
A32: MN Biên Hòa | J32: =SUM(K32:V32) -> 12 | K32: =SUM(K33:K36) -> 10 | L32: =SUM(L33:L36) -> 2 | M32: =SUM(M33:M36) -> 0 | N32: =SUM(N33:N36) -> 0 | O32: =SUM(O33:O36) -> 0 | P32: =SUM(P33:P36) -> 0 | Q32: =SUM(Q33:Q36) -> 0 | R32: =SUM(R33:R36) -> 0 | ... V32: =SUM(V33:V36) -> 0 | W32: MN Biên Hòa | X32: =SUM(Y32:AK32) -> 22 | Y32: =SUM(Y33:Y36) -> 12 | Z32: =SUM(Z33:Z36) -> 10 | AA32: =SUM(AA33:AA36) -> 0 | AB32: =SUM(AB33:AB36) -> 0 | AC32: =SUM(AC33:AC36) -> 0 | AD32: =SUM(AD33:AD36) -> 0 | AE32: =SUM(AE33:AE36) -> 0 | AF32: =SUM(AF33:AF36) -> 0 | ... AJ32: =SUM(AJ33:AJ36) -> 0 | AK32: MN Biên Hòa | AL32: =X32-J32 -> 10 | AM32: =Y32-K32 -> 2 | AN32: =Z32-L32 -> 8 | AO32: =AA32-M32 -> 0 | AP32: =AB32-N32 -> 0 | AQ32: =AC32-O32 -> 0 | AR32: =AD32-P32 -> 0 | AS32: =AE32-Q32 -> 0 | ... AX32: =AJ32-V32 -> 0
A33: Nhà trẻ | J33: =SUM(K33:V33) -> 6 | K33: 5 | L33: 1 | W33: Nhà trẻ | X33: =SUM(Y33:AK33) -> 12 | Y33: 7 | Z33: 5 | AK33: Nhà trẻ | AL33: =X33-J33 -> 6 | AM33: =Y33-K33 -> 2 | AN33: =Z33-L33 -> 4 | AO33: =AA33-M33 -> 0 | AP33: =AB33-N33 -> 0 | AQ33: =AC33-O33 -> 0 | AR33: =AD33-P33 -> 0 | AS33: =AE33-Q33 -> 0 | ... AX33: =AJ33-V33 -> 0
A34: Mầm | J34: =SUM(K34:V34) -> 2 | K34: 2 | W34: Mầm | X34: =SUM(Y34:AK34) -> 3 | Z34: 3 | AK34: Mầm | AL34: =X34-J34 -> 1 | AM34: =Y34-K34 -> -2 | AN34: =Z34-L34 -> 3 | AO34: =AA34-M34 -> 0 | AP34: =AB34-N34 -> 0 | AQ34: =AC34-O34 -> 0 | AR34: =AD34-P34 -> 0 | AS34: =AE34-Q34 -> 0 | ... AX34: =AJ34-V34 -> 0
A35: Chồi | J35: =SUM(K35:V35) -> 2 | K35: 1 | L35: 1 | W35: Chồi | X35: =SUM(Y35:AK35) -> 3 | Y35: 2 | Z35: 1 | AK35: Chồi | AL35: =X35-J35 -> 1 | AM35: =Y35-K35 -> 1 | AN35: =Z35-L35 -> 0 | AO35: =AA35-M35 -> 0 | AP35: =AB35-N35 -> 0 | AQ35: =AC35-O35 -> 0 | AR35: =AD35-P35 -> 0 | AS35: =AE35-Q35 -> 0 | ... AX35: =AJ35-V35 -> 0
A36: Lá | J36: =SUM(K36:V36) -> 2 | K36: 2 | W36: Lá | X36: =SUM(Y36:AK36) -> 4 | Y36: 3 | Z36: 1 | AK36: Lá | AL36: =X36-J36 -> 2 | AM36: =Y36-K36 -> 1 | AN36: =Z36-L36 -> 1 | AO36: =AA36-M36 -> 0 | AP36: =AB36-N36 -> 0 | AQ36: =AC36-O36 -> 0 | AR36: =AD36-P36 -> 0 | AS36: =AE36-Q36 -> 0 | ... AX36: =AJ36-V36 -> 0
A37: MN Long Khánh | J37: =SUM(K37:V37) -> 10 | K37: =SUM(K38:K41) -> 6 | L37: =SUM(L38:L41) -> 4 | M37: =SUM(M38:M41) -> 0 | N37: =SUM(N38:N41) -> 0 | O37: =SUM(O38:O41) -> 0 | P37: =SUM(P38:P41) -> 0 | Q37: =SUM(Q38:Q41) -> 0 | R37: =SUM(R38:R41) -> 0 | ... V37: =SUM(V38:V41) -> 0 | W37: MN Long Khánh | X37: =SUM(Y37:AK37) -> 22 | Y37: =SUM(Y38:Y41) -> 14 | Z37: =SUM(Z38:Z41) -> 8 | AA37: =SUM(AA38:AA41) -> 0 | AB37: =SUM(AB38:AB41) -> 0 | AC37: =SUM(AC38:AC41) -> 0 | AD37: =SUM(AD38:AD41) -> 0 | AE37: =SUM(AE38:AE41) -> 0 | AF37: =SUM(AF38:AF41) -> 0 | ... AJ37: =SUM(AJ38:AJ41) -> 0 | AK37: MN Long Khánh | AL37: =X37-J37 -> 12 | AM37: =Y37-K37 -> 8 | AN37: =Z37-L37 -> 4 | AO37: =AA37-M37 -> 0 | AP37: =AB37-N37 -> 0 | AQ37: =AC37-O37 -> 0 | AR37: =AD37-P37 -> 0 | AS37: =AE37-Q37 -> 0 | ... AX37: =AJ37-V37 -> 0
A38: Nhà trẻ | J38: =SUM(K38:V38) -> 4 | K38: 3 | L38: 1 | W38: Nhà trẻ | X38: =SUM(Y38:AK38) -> 13 | Y38: 8 | Z38: 5 | AK38: Nhà trẻ | AL38: =X38-J38 -> 9 | AM38: =Y38-K38 -> 5 | AN38: =Z38-L38 -> 4 | AO38: =AA38-M38 -> 0 | AP38: =AB38-N38 -> 0 | AQ38: =AC38-O38 -> 0 | AR38: =AD38-P38 -> 0 | AS38: =AE38-Q38 -> 0 | ... AX38: =AJ38-V38 -> 0
A39: Mầm | J39: =SUM(K39:V39) -> 5 | K39: 2 | L39: 3 | W39: Mầm | X39: =SUM(Y39:AK39) -> 1 | Z39: 1 | AK39: Mầm | AL39: =X39-J39 -> -4 | AM39: =Y39-K39 -> -2 | AN39: =Z39-L39 -> -2 | AO39: =AA39-M39 -> 0 | AP39: =AB39-N39 -> 0 | AQ39: =AC39-O39 -> 0 | AR39: =AD39-P39 -> 0 | AS39: =AE39-Q39 -> 0 | ... AX39: =AJ39-V39 -> 0
A40: Chồi | J40: =SUM(K40:V40) -> 1 | K40: 1 | W40: Chồi | X40: =SUM(Y40:AK40) -> 5 | Y40: 4 | Z40: 1 | AK40: Chồi | AL40: =X40-J40 -> 4 | AM40: =Y40-K40 -> 3 | AN40: =Z40-L40 -> 1 | AO40: =AA40-M40 -> 0 | AP40: =AB40-N40 -> 0 | AQ40: =AC40-O40 -> 0 | AR40: =AD40-P40 -> 0 | AS40: =AE40-Q40 -> 0 | ... AX40: =AJ40-V40 -> 0
A41: Lá | J41: =SUM(K41:V41) -> 0 | W41: Lá | X41: =SUM(Y41:AK41) -> 3 | Y41: 2 | Z41: 1 | AK41: Lá | AL41: =X41-J41 -> 3 | AM41: =Y41-K41 -> 2 | AN41: =Z41-L41 -> 1 | AO41: =AA41-M41 -> 0 | AP41: =AB41-N41 -> 0 | AQ41: =AC41-O41 -> 0 | AR41: =AD41-P41 -> 0 | AS41: =AE41-Q41 -> 0 | ... AX41: =AJ41-V41 -> 0
A42: Tiểu học | J42: =SUM(K42:V42) -> 14 | K42: =SUM(K43:K47) -> 12 | L42: =SUM(L43:L47) -> 2 | M42: =SUM(M43:M47) -> 0 | N42: =SUM(N43:N47) -> 0 | O42: =SUM(O43:O47) -> 0 | P42: =SUM(P43:P47) -> 0 | Q42: =SUM(Q43:Q47) -> 0 | R42: =SUM(R43:R47) -> 0 | ... V42: =SUM(V43:V47) -> 0 | W42: Tiểu học | X42: =SUM(Y42:AK42) -> 82 | Y42: =SUM(Y43:Y47) -> 81 | Z42: =SUM(Z43:Z47) -> 1 | AA42: =SUM(AA43:AA47) -> 0 | AB42: =SUM(AB43:AB47) -> 0 | AC42: =SUM(AC43:AC47) -> 0 | AD42: =SUM(AD43:AD47) -> 0 | AE42: =SUM(AE43:AE47) -> 0 | AF42: =SUM(AF43:AF47) -> 0 | ... AJ42: =SUM(AJ43:AJ47) -> 0 | AK42: Tiểu học | AL42: =X42-J42 -> 68 | AM42: =Y42-K42 -> 69 | AN42: =Z42-L42 -> -1 | AO42: =AA42-M42 -> 0 | AP42: =AB42-N42 -> 0 | AQ42: =AC42-O42 -> 0 | AR42: =AD42-P42 -> 0 | AS42: =AE42-Q42 -> 0 | ... AX42: =AJ42-V42 -> 0
...

Sheet 2. Câu lạc bộ
C1: Cơ sở/ Khối lớp | D1: Chỉ tiêu CLB | E1: Tháng 9 | F1: Tháng 10 | G1: Tháng 11 | H1: Tháng 12 | I1: Tháng 1 | J1: Tháng 2 | K1: Tháng 3 | L1: Tháng 4 | M1: Tháng 5 | N1: % chỉ tiêu Tháng 9 | O1: % chỉ tiêu Tháng 10 | P1: % chỉ tiêu Tháng 11 | Q1: % chỉ tiêu Tháng 12 | R1: % chỉ tiêu Tháng 1 | S1: % chỉ tiêu Tháng 2 | T1: % chỉ tiêu Tháng 3 | U1: % chỉ tiêu Tháng 4 | V1: % chỉ tiêu Tháng 5
C2: Mầm non Biên Hòa | D2: =D51 -> 120 | E2: =E51 -> 77 | F2: =F51 -> 0 | G2: =G51 -> 0 | H2: =H51 -> 0 | I2: =I51 -> 0 | J2: =J51 -> 0 | K2: =K51 -> 0 | ... M2: =M51 -> 0 | N2: =E2/$D2 -> 0.64166667 | O2: =F2/$D2 -> 0 | P2: =G2/$D2 -> 0 | Q2: =H2/$D2 -> 0 | R2: =I2/$D2 -> 0 | S2: =J2/$D2 -> 0 | T2: =K2/$D2 -> 0 | U2: =L2/$D2 -> 0 | V2: =M2/$D2 -> 0
C3: Mầm non Long Khánh | D3: =D58 -> 75 | E3: =E58 -> 70 | F3: =F58 -> 0 | G3: =G58 -> 0 | H3: =H58 -> 0 | I3: =I58 -> 0 | J3: =J58 -> 0 | K3: =K58 -> 0 | ... M3: =M58 -> 0 | N3: =E3/$D3 -> 0.93333333 | O3: =F3/$D3 -> 0 | P3: =G3/$D3 -> 0 | Q3: =H3/$D3 -> 0 | R3: =I3/$D3 -> 0 | S3: =J3/$D3 -> 0 | T3: =K3/$D3 -> 0 | U3: =L3/$D3 -> 0 | V3: =M3/$D3 -> 0
C4: Tiểu học | D4: =D41 -> 300 | E4: =E41 -> 353 | F4: =F41 -> 0 | G4: =G41 -> 0 | H4: =H41 -> 0 | I4: =I41 -> 0 | J4: =J41 -> 0 | K4: =K41 -> 0 | ... M4: =M41 -> 0 | N4: =E4/$D4 -> 1.1766667 | O4: =F4/$D4 -> 0 | P4: =G4/$D4 -> 0 | Q4: =H4/$D4 -> 0 | R4: =I4/$D4 -> 0 | S4: =J4/$D4 -> 0 | T4: =K4/$D4 -> 0 | U4: =L4/$D4 -> 0 | V4: =M4/$D4 -> 0
C5: Trung học | D5: =D19 -> 150 | E5: =E19 -> 96 | F5: =F19 -> 0 | G5: =G19 -> 0 | H5: =H19 -> 0 | I5: =I19 -> 0 | J5: =J19 -> 0 | K5: =K19 -> 0 | ... M5: =M19 -> 0 | N5: =E5/$D5 -> 0.64 | O5: =F5/$D5 -> 0 | P5: =G5/$D5 -> 0 | Q5: =H5/$D5 -> 0 | R5: =I5/$D5 -> 0 | S5: =J5/$D5 -> 0 | T5: =K5/$D5 -> 0 | U5: =L5/$D5 -> 0 | V5: =M5/$D5 -> 0
B8: Môn học | C8: Cấp học | D8: Chỉ tiêu | E8: Tháng 9 | F8: Tháng 10 | G8: Tháng 11 | H8: Tháng 12 | I8: Tháng 1 | J8: Tháng 2 | K8: Tháng 3 | L8: Tháng 4 | M8: Tháng 5
A9: CLB Ẩm thực - Thứ 3 & Thứ 5 | B9: CLB Advanced Robotics | C9: Trung học | D9: 15 | E9: 5
A10: CLB Bóng đá - Thứ 3 & Thứ 5 | B10: CLB Ẩm thực | C10: Trung học | D10: 15 | E10: 5
A11: CLB Bóng rổ - Thứ 7 | B11: CLB Bơi nâng cao 2 | C11: Trung học | D11: 15 | E11: 15
A12: CLB Cầu lông - Pickleball - Thứ 3 & Thứ 5 | B12: CLB Bóng chuyền | C12: Trung học | D12: 15 | E12: 8
B13: CLB Bóng đá | C13: Trung học | D13: 15 | E13: 12
A14: CLB Aerobic cơ bản - Thứ 2 & Thứ 4 | B14: CLB Bóng đá phát triển | C14: Trung học | D14: 15 | E14: 14
B15: CLB Bóng rổ | C15: Trung học | D15: 15 | E15: 5
A16: CLB Aerobic nâng cao - Thứ 3 & Thứ 5 | B16: CLB Digital - Art | C16: Trung học | D16: 15 | E16: 15
A17: CLB AI Robotics 3,4,5 - Thứ 3 & Thứ 5 | B17: CLB Nhảy hiện đại | C17: Trung học | D17: 15 | E17: 9
A18: CLB Bơi lội - Thứ 2 & Thứ 4 | B18: CLB Tiếng Trung | C18: Trung học | D18: 15 | E18: 8
A19: CLB Bơi - Thứ 3 & Thứ 5 | D19: =SUM(D9:D18) -> 150 | E19: =SUM(E9:E18) -> 96 | F19: =SUM(F9:F18) -> 0 | G19: =SUM(G9:G18) -> 0 | H19: =SUM(H9:H18) -> 0 | I19: =SUM(I9:I18) -> 0 | J19: =SUM(J9:J18) -> 0 | K19: =SUM(K9:K18) -> 0 | ... M19: =SUM(M9:M18) -> 0
B20: Môn học | C20: Cấp học | D20: Chỉ tiêu | E20: Tháng 9 | F20: Tháng 10 | G20: Tháng 11 | H20: Tháng 12 | I20: Tháng 1 | J20: Tháng 2 | K20: Tháng 3 | L20: Tháng 4 | M20: Tháng 5
A21: CLB Bóng đá - Thứ 2 & Thứ 4 | B21: CLB Aerobic | C21: Tiểu học | D21: 15 | E21: 18
A22: CLB Bóng rổ - Thứ 2 & Thứ 4 | B22: CLB Ẩm thực | C22: Tiểu học | D22: 15 | E22: 16
B23: CLB Bơi lội cơ bản | C23: Tiểu học | D23: 15 | E23: 20
B24: CLB Bơi nâng cao | C24: Tiểu học | D24: 15 | E24: 22
B25: CLB Bóng đá | C25: Tiểu học | D25: 15 | E25: 30
B26: CLB Bóng đá Nhí | C26: Tiểu học | D26: 15 | E26: 29
A27: CLB Bóng rổ - Thứ 3 & Thứ 5 | B27: CLB Bóng rổ | C27: Tiểu học | D27: 15 | E27: 17
A28: CLB Cờ vua - Thứ 2 & Thứ 4 | B28: CLB Cờ vua | C28: Tiểu học | D28: 15 | E28: 19
A29: CLB Digital art - Nghệ thuật số - Thứ 2 & Thứ 4 | B29: CLB Digital - Art | C29: Tiểu học | D29: 15 | E29: 28
A30: CLB Lập trình game - Thứ 2 & Thứ 4 | B30: CLB Hội hoạ cơ bản | C30: Tiểu học | D30: 15 | E30: 25
A31: CLB Tiếng anh TA1 K1 - Thứ 2 & Thứ 4 | B31: CLB Khoa học vui | C31: Tiểu học | D31: 15 | E31: 0
A32: CLB Võ Vovinam - Thứ 2 & Thứ 4 | B32: CLB Lập trình Game | C32: Tiểu học | D32: 15 | E32: 9
A33: CLB Tiếng anh TA2 K 2,3 - Thứ 2 & Thứ 4 | B33: CLB Nhảy hiện đại | C33: Tiểu học | D33: 15 | E33: 13
A34: CLB Bóng đá - Thứ 3 & Thứ 5 | B34: CLB Robotics - Plus (Khối 1) | C34: Tiểu học | D34: 15 | E34: 11
B35: CLB Robotics Enrichment | C35: Tiểu học | D35: 15 | E35: 21
A36: CLB Aerobic - Thứ 2 & Thứ 4 | B36: CLB Robotics Extended | C36: Tiểu học | D36: 15 | E36: 10
A37: CLB Aerobic - Thứ 3 & Thứ 5 | B37: CLB Tiếng anh Lễ Hội Bốn Phương - Khối 2, 3 | C37: Tiểu học | D37: 15 | E37: 17
A38: CLB Bơi - Thứ 3 & Thứ 5 | B38: CLB Tiếng anh Nhà Khám Phá Nhí- Khối 1 | C38: Tiểu học | D38: 15 | E38: 15
A39: CLB Rèn chữ - Thứ 2 & Thứ 4 | B39: CLB Tiếng anh Nói Hay Tự Tin | C39: Tiểu học | D39: 15 | E39: 14
A40: CLB Tiếng anh - Thứ 2 & Thứ 4 | B40: CLB Võ Việt Nam | C40: Tiểu học | D40: 15 | E40: 19
A41: CLB Tiếng anh - Thứ 3 & Thứ 5 | D41: =SUM(D21:D40) -> 300 | E41: =SUM(E21:E40) -> 353 | F41: =SUM(F21:F40) -> 0 | G41: =SUM(G21:G40) -> 0 | H41: =SUM(H21:H40) -> 0 | I41: =SUM(I21:I40) -> 0 | J41: =SUM(J21:J40) -> 0 | K41: =SUM(K21:K40) -> 0 | ... N41: =SUM(N21:N40) -> 0
B42: Môn học | C42: Cấp học | D42: Chỉ tiêu | E42: Tháng 9 | F42: Tháng 10 | G42: Tháng 11 | H42: Tháng 12 | I42: Tháng 1 | J42: Tháng 2 | K42: Tháng 3 | L42: Tháng 4 | M42: Tháng 5
...

Sheet 3. Tiết dạy
A1: STT | B1: Cap | C1: Thu | D1: Ngay | E1: Buoi | F1: Tiet | G1: TenLop | H1: TenMonHoc | I1: GiaoVienPhuTrach | J1: GV dạy thay | K1: Tên GV dạy thay | L1: Số tiết chưa được bù | M1: Tháng
A2: 1 | B2: Cấp 1 | C2: 2 | D2: 28/09/2026 | E2: Chiều | F2: 5 | G2: 26CLB-BC_D1 | H2: Câu lạc bộ | I2: Trần Đức Thanh | J2: Giáo viên | L2: 1 | M2: 8 | P2: Row Labels | Q2: Count of Tiet | R2: Sum of Số tiết chưa được bù
A3: 2 | B3: Cấp 1 | C3: 2 | D3: 28/09/2026 | E3: Chiều | F3: 4 | G3: 26CLB-BD_B1 | H3: Bóng đá | I3: Trần Đắc Mùi | J3: Giáo viên | L3: 1 | M3: 8 | P3: Âm nhạc | Q3: 3
A4: 3 | B4: Cấp 1 | C4: 2 | D4: 28/09/2026 | E4: Chiều | F4: 4 | G4: 26CLB-BD_A1 | H4: Bóng đá | I4: Dương Kim Cương | J4: Giáo viên | L4: 1 | M4: 8 | P4: Bóng đá | Q4: 6 | R4: 6
A5: 4 | B5: Cấp 3 | C5: 6 | D5: 25/09/2026 | E5: Chiều | F5: 3 | G5: 11A | H5: Ngữ văn | I5: Trần Thuỳ Dung | J5: Giáo viên | L5: 1 | M5: 8 | P5: Bóng rổ | Q5: 1 | R5: 1
A6: 5 | B6: Cấp 2 | C6: 5 | D6: 24/09/2026 | E6: Chiều | F6: 3 | G6: 06E | H6: Ngữ văn | I6: Trần Thuỳ Dung | J6: Giáo viên | L6: 1 | M6: 8 | P6: Câu lạc bộ | Q6: 2 | R6: 2
A7: 6 | B7: Cấp 1 | C7: 4 | D7: 23/09/2026 | E7: Chiều | F7: 5 | G7: 26CLB-BC_D1 | H7: Câu lạc bộ | I7: Trần Đức Thanh | J7: Giáo viên | L7: 1 | M7: 8 | P7: Câu lạc bộ bơi | Q7: 2 | R7: 2
A8: 7 | B8: Cấp 1 | C8: 4 | D8: 23/09/2026 | E8: Chiều | F8: 4 | G8: 26CLB-BR_B1 | H8: Bóng rổ | I8: Nguyễn Quang Thịnh | J8: Giáo viên | L8: 1 | M8: 8 | P8: Chuyên đề HT Lý | Q8: 1
A9: 8 | B9: Cấp 1 | C9: 4 | D9: 23/09/2026 | E9: Chiều | F9: 4 | G9: 26CLB-BD_B1 | H9: Bóng đá | I9: Trần Đắc Mùi | J9: Giáo viên | L9: 1 | M9: 8 | P9: Chuyên đề HT Toán | Q9: 1
A10: 9 | B10: Cấp 1 | C10: 4 | D10: 23/09/2026 | E10: Chiều | F10: 4 | G10: 26CLB-BD_A1 | H10: Bóng đá | I10: Dương Kim Cương | J10: Giáo viên | L10: 1 | M10: 8 | P10: Công nghệ | Q10: 1
A11: 10 | B11: Cấp 1 | C11: 3 | D11: 22/09/2026 | E11: Chiều | F11: 5 | G11: 26CLB-BD_C2 | H11: Bóng đá | I11: Dương Kim Cương | J11: Giáo viên | L11: 1 | M11: 8 | P11: HĐ Trải nghiệm GVBM | Q11: 1
A12: 11 | B12: Cấp 1 | C12: 3 | D12: 22/09/2026 | E12: Chiều | F12: 5 | G12: 26CLB-Boi_C1 | H12: Câu lạc bộ bơi | I12: Tống Mỹ Kiều Loan | J12: Giáo viên | L12: 1 | M12: 8 | P12: HĐ Trải nghiệm GVCN | Q12: 2
A13: 12 | B13: Cấp 1 | C13: 3 | D13: 22/09/2026 | E13: Chiều | F13: 4 | G13: 26CLB-Boi_B1 | H13: Câu lạc bộ bơi | I13: Trần Đức Thanh | J13: Giáo viên | L13: 1 | M13: 8 | P13: Hóa học | Q13: 1 | R13: 1
A14: 13 | B14: Cấp 1 | C14: 3 | D14: 22/09/2026 | E14: Chiều | F14: 4 | G14: 26CLB-BD_C1 | H14: Bóng đá | I14: Trần Đắc Mùi | J14: Giáo viên | L14: 1 | M14: 8 | P14: JA | Q14: 3
A15: 14 | B15: Cấp 2 | C15: 2 | D15: 14/09/2026 | E15: Sáng | F15: 2 | G15: 06F | H15: Ngữ văn | I15: Trịnh Văn Tự | L15: 1 | M15: 8 | P15: Khoa học | Q15: 1
A16: 15 | B16: Cấp 2 | C16: 2 | D16: 14/09/2026 | E16: Sáng | F16: 1 | G16: 08B | H16: Ngữ văn | I16: Trịnh Văn Tự | L16: 1 | M16: 8 | P16: Khoa học tự nhiên | Q16: 3
A17: 16 | B17: Cấp 0 | C17: 3 | D17: 08/09/2026 | E17: Chiều | F17: 4 | G17: 26CLBMNLK-TA-A1-TG | H17: Tiếng Anh - GVNN | I17: Nguyễn Thị Bích Trâm | J17: GV Mầm non | L17: 1 | M17: 8 | P17: Lịch sử và địa lý | Q17: 1
A18: 17 | B18: Cấp 3 | C18: 6 | D18: 04/09/2026 | E18: Chiều | F18: 4 | G18: 10C | H18: Sinh hoạt | I18: La Gia Nghi | J18: Giáo viên | L18: 1 | M18: 8 | P18: Ngữ văn | Q18: 12 | R18: 4
A19: 18 | B19: Cấp 3 | C19: 6 | D19: 04/09/2026 | E19: Chiều | F19: 4 | G19: 10A | H19: Sinh hoạt | I19: Lê Thị Hạnh | J19: Giáo viên | L19: 1 | M19: 8 | P19: Sinh hoạt | Q19: 4 | R19: 2
A20: 19 | B20: Cấp 3 | C20: 6 | D20: 04/09/2026 | E20: Chiều | F20: 3 | G20: 10B | H20: Hóa học | I20: Lê Thị Hạnh | J20: Giáo viên | L20: 1 | M20: 8 | P20: STEM trải nghiệm | Q20: 4
A21: 20 | B21: Cấp 3 | C21: 4 | D21: 30/09/2026 | E21: Chiều | F21: 4 | G21: 10AV2 | H21: TA tích hợp GVNN | I21: Lopez Anne Julia Redor | J21: GV nước ngoài | K21: Carreon Gugol Vanessa Ariane | M21: 8 | P21: TA tích hợp GVNN | Q21: 8
A22: 21 | B22: Cấp 1 | C22: 4 | D22: 30/09/2026 | E22: Chiều | F22: 4 | G22: 04B | H22: Lịch sử và địa lý | I22: Lê Thị Thanh Huyền | J22: GV Tiểu học | K22: Nguyễn Thị Nga | M22: 8 | P22: TA tích hợp GVVN | Q22: 26
A23: 22 | B23: Cấp 1 | C23: 4 | D23: 30/09/2026 | E23: Chiều | F23: 4 | G23: 05A | H23: Tiếng Việt | I23: Phạm Thị Mỹ Yến | J23: GV Tiểu học | K23: Phạm Lê Uyễn Nhi | M23: 8 | P23: Tiếng Anh - GVNN | Q23: 3 | R23: 1
A24: 23 | B24: Cấp 3 | C24: 4 | D24: 30/09/2026 | E24: Chiều | F24: 3 | G24: 10AV2 | H24: TA tích hợp GVNN | I24: Lopez Anne Julia Redor | J24: GV nước ngoài | K24: Carreon Gugol Vanessa Ariane | M24: 8 | P24: Tiếng Anh - GVVN | Q24: 12
A25: 24 | B25: Cấp 1 | C25: 4 | D25: 30/09/2026 | E25: Chiều | F25: 3 | G25: 04B | H25: Toán | I25: Lê Thị Thanh Huyền | J25: GV Tiểu học | K25: Nguyễn Thị Nga | M25: 8 | P25: Tiếng Việt | Q25: 16
A26: 25 | B26: Cấp 1 | C26: 4 | D26: 30/09/2026 | E26: Chiều | F26: 3 | G26: 05A | H26: Tiếng Việt | I26: Phạm Thị Mỹ Yến | J26: GV Tiểu học | K26: Thạch Thị Sa My | M26: 8 | P26: Tin học | Q26: 2
A27: 26 | B27: Cấp 1 | C27: 4 | D27: 30/09/2026 | E27: Chiều | F27: 2 | G27: 04B | H27: Tiếng Việt | I27: Lê Thị Thanh Huyền | J27: GV Tiểu học | K27: Tống Thị Lan Anh | M27: 8 | P27: Toán | Q27: 22
A28: 27 | B28: Cấp 1 | C28: 4 | D28: 30/09/2026 | E28: Chiều | F28: 1 | G28: 04B | H28: Tiếng Việt | I28: Lê Thị Thanh Huyền | J28: GV Tiểu học | K28: Tống Thị Lan Anh | M28: 8 | P28: Tự nhiên xã hội | Q28: 2
A29: 28 | B29: Cấp 1 | C29: 4 | D29: 30/09/2026 | E29: Chiều | F29: 1 | G29: 05A | H29: Toán | I29: Phạm Thị Mỹ Yến | J29: GV Tiểu học | K29: Đoàn Ngọc Nhi | M29: 8 | P29: Vật lí | Q29: 4
A30: 29 | B30: Cấp 2 | C30: 4 | D30: 30/09/2026 | E30: Sáng | F30: 4 | G30: 06G | H30: TA tích hợp GVVN | I30: Đỗ Thị Duyên | J30: Giáo viên | K30: Nguyễn Thị Thanh Thùy | M30: 8 | P30: Grand Total | Q30: 144 | R30: 19
A31: 30 | B31: Cấp 2 | C31: 4 | D31: 30/09/2026 | E31: Sáng | F31: 3 | G31: 06G | H31: TA tích hợp GVVN | I31: Đỗ Thị Duyên | J31: Giáo viên | K31: Nguyễn Thị Thanh Thùy | M31: 8
A32: 31 | B32: Cấp 2 | C32: 4 | D32: 30/09/2026 | E32: Sáng | F32: 2 | G32: 06B | H32: TA tích hợp GVVN | I32: Đỗ Thị Duyên | J32: Giáo viên | K32: Nguyễn Thị Thanh Thùy | M32: 8
A33: 32 | B33: Cấp 2 | C33: 4 | D33: 30/09/2026 | E33: Sáng | F33: 1 | G33: 06B | H33: TA tích hợp GVVN | I33: Đỗ Thị Duyên | J33: Giáo viên | K33: Nguyễn Thị Thanh Thùy | M33: 8
A34: 33 | B34: Cấp 1 | C34: 3 | D34: 29/09/2026 | E34: Chiều | F34: 4 | G34: 05D | H34: Khoa học | I34: Thạch Thị Sa My | J34: GV Tiểu học | K34: Trịnh Ngọc Bảo Trân | M34: 8
A35: 34 | B35: Cấp 1 | C35: 3 | D35: 29/09/2026 | E35: Chiều | F35: 3 | G35: 05D | H35: HĐ Trải nghiệm GVCN | I35: Thạch Thị Sa My | J35: GV Tiểu học | K35: Nguyễn Thị Kiều Duyên | M35: 8
A36: 35 | B36: Cấp 1 | C36: 3 | D36: 29/09/2026 | E36: Chiều | F36: 2 | G36: 05D | H36: Toán | I36: Thạch Thị Sa My | J36: GV Tiểu học | K36: Nguyễn Thị Kiều Duyên | M36: 8
A37: 36 | B37: Cấp 1 | C37: 3 | D37: 29/09/2026 | E37: Chiều | F37: 1 | G37: 05D | H37: JA | I37: Thạch Thị Sa My | J37: GV Tiểu học | K37: Lê Thuỷ Tiên | M37: 8
A38: 37 | B38: Cấp 2 | C38: 3 | D38: 29/09/2026 | E38: Sáng | F38: 4 | G38: 06F | H38: TA tích hợp GVVN | I38: Đỗ Thị Duyên | J38: Giáo viên | K38: Trần Thanh Tâm | M38: 8
A39: 38 | B39: Cấp 2 | C39: 3 | D39: 29/09/2026 | E39: Sáng | F39: 3 | G39: 06F | H39: TA tích hợp GVVN | I39: Đỗ Thị Duyên | J39: Giáo viên | K39: Trần Thanh Tâm | M39: 8
A40: 39 | B40: Cấp 1 | C40: 3 | D40: 29/09/2026 | E40: Sáng | F40: 3 | G40: 05D | H40: Tiếng Việt | I40: Thạch Thị Sa My | J40: GV Tiểu học | K40: Nguyễn Thị Kiều Duyên | M40: 8
...

Sheet 4. Khám sức khỏe
A1: Nhóm bệnh | B1: Loại bệnh | C1: HS mầm non | D1: HS tiểu học | E1: HS THCS | F1: HS THPT | G1: Tổng số lượt khám | H1: Lượt khám mầm non | I1: Lượt khám Tiểu học | J1: Lượt khám THCS | K1: Lượt khám THPT | L1: Tháng | O1: Học sinh mầm non | P1: Học sinh tiểu học | Q1: Học sinh cấp 2 | R1: Học sinh cấp 3
A2: Bệnh truyền nhiễm | B2: Sốt | C2: 37 | D2: 35 | E2: 18 | F2: 4 | G2: 113 | H2: 51 | I2: 39 | J2: 19 | K2: 4 | L2: 8 | N2: Tỷ lệ chăm sóc theo cấp | O2: =O3/SUM($O$3:$S$3) -> 0.084349098 | P2: =P3/SUM($O$3:$S$3) -> 0.41491955 | Q2: =Q3/SUM($O$3:$S$3) -> 0.35104827 | R2: =R3/SUM($O$3:$S$3) -> 0.14968308
A3: Bệnh truyền nhiễm | B3: Bỏng | C3: 0 | D3: 0 | E3: 0 | F3: 1 | G3: 1 | H3: 0 | I3: 0 | J3: 0 | K3: 1 | L3: 8 | N3: Tổng cộng | O3: =SUM(C:C) -> 173 | P3: =SUM(D:D) -> 851 | Q3: =SUM(E:E) -> 720 | R3: =SUM(F:F) -> 307
A4: Bỏng da | B4: Bỏng độ 1 | C4: 2 | D4: 4 | E4: 3 | F4: 1 | G4: 10 | H4: 2 | I4: 4 | J4: 3 | K4: 1 | L4: 8
A5: Chấn thương | B5: Đau nhức do va chạm / chơi thể thao | C5: 0 | D5: 27 | E5: 26 | F5: 10 | G5: 70 | H5: 0 | I5: 29 | J5: 31 | K5: 10 | L5: 8 | N5: Sum of Lượt khám mầm non | O5: Column Labels
A6: Chấn thương | B6: Đau mỏi cơ | C6: 0 | D6: 10 | E6: 24 | F6: 8 | G6: 48 | H6: 0 | I6: 11 | J6: 27 | K6: 10 | L6: 8 | N6: Row Labels | O6: 9 | P6: Grand Total
A7: Chấn thương | B7: Chấn thương phần mềm | C7: 1 | D7: 6 | E7: 9 | F7: 3 | G7: 19 | H7: 1 | I7: 6 | J7: 9 | K7: 3 | L7: 8 | N7: Bệnh truyền nhiễm | O7: 97 | P7: 97
A8: Da liễu | B8: TD Dị ứng da do tiếp xúc | C8: 0 | D8: 5 | E8: 0 | F8: 1 | G8: 7 | H8: 0 | I8: 5 | J8: 0 | K8: 2 | L8: 8 | N8: Bỏng da | O8: 0 | P8: 0
A9: Da liễu | B9: Dị ứng da ( Mề đay dị ứng ) | C9: 2 | D9: 2 | E9: 0 | F9: 1 | G9: 5 | H9: 2 | I9: 2 | J9: 0 | K9: 1 | L9: 8 | N9: Chấn thương | O9: 1 | P9: 1
A10: Da liễu | B10: Dị ứng do thức ăn | C10: 0 | D10: 2 | E10: 0 | F10: 1 | G10: 3 | H10: 0 | I10: 2 | J10: 0 | K10: 1 | L10: 8 | N10: Da liễu | O10: 5 | P10: 5
A11: Da liễu | B11: Viêm da cơ địa | C11: 0 | D11: 0 | E11: 0 | F11: 1 | G11: 1 | H11: 0 | I11: 0 | J11: 0 | K11: 1 | L11: 8 | N11: Hô hấp | O11: 1 | P11: 1
A12: Da liễu | B12: Mụn viêm | C12: 0 | D12: 4 | E12: 0 | F12: 0 | G12: 4 | H12: 0 | I12: 4 | J12: 0 | K12: 0 | L12: 8 | N12: Mắt | O12: 3 | P12: 3
A13: Da liễu | B13: Viêm da dị ứng | C13: 0 | D13: 3 | E13: 0 | F13: 0 | G13: 3 | H13: 0 | I13: 3 | J13: 0 | K13: 0 | L13: 8 | N13: Răng hàm mặt | O13: 0 | P13: 0
A14: Da liễu | B14: Kích ứng da | C14: 1 | D14: 1 | E14: 0 | F14: 0 | G14: 2 | H14: 1 | I14: 1 | J14: 0 | K14: 0 | L14: 8 | N14: Tai mũi họng | O14: 3 | P14: 3
A15: Da liễu | B15: Viêm da | C15: 0 | D15: 2 | E15: 0 | F15: 0 | G15: 2 | H15: 0 | I15: 2 | J15: 0 | K15: 0 | L15: 8 | N15: Thận - Tiết niệu | O15: 0 | P15: 0
A16: Da liễu | B16: Chính mé | C16: 0 | D16: 1 | E16: 0 | F16: 0 | G16: 1 | H16: 0 | I16: 1 | J16: 0 | K16: 0 | L16: 8 | N16: Tiêu hoá | O16: 0 | P16: 0
A17: Hô hấp | B17: Viêm đường hô hấp trên | C17: 2 | D17: 5 | E17: 14 | F17: 7 | G17: 29 | H17: 2 | I17: 5 | J17: 15 | K17: 7 | L17: 8 | N17: Tim mạch | O17: 0 | P17: 0
A18: Hô hấp | B18: Viêm phế quản | C18: 0 | D18: 1 | E18: 0 | F18: 0 | G18: 1 | H18: 0 | I18: 1 | J18: 0 | K18: 0 | L18: 8 | N18: Tổng hợp | O18: 6 | P18: 6
... A20: Mắt | B20: Tăng điều tiết mắt | C20: 0 | D20: 2 | E20: 2 | F20: 0 | G20: 6 | H20: 0 | I20: 2 | J20: 4 | K20: 0 | L20: 8 | N20: Grand Total | O20: 124 | P20: 124
A21: Mắt | B21: Viêm mi mắt | C21: 0 | D21: 2 | E21: 3 | F21: 0 | G21: 5 | H21: 0 | I21: 2 | J21: 3 | K21: 0 | L21: 8
A22: Mắt | B22: Đau mắt | C22: 0 | D22: 3 | E22: 1 | F22: 0 | G22: 4 | H22: 0 | I22: 3 | J22: 1 | K22: 0 | L22: 8
A23: Mắt | B23: Chắp, lẹo mắt | C23: 0 | D23: 2 | E23: 0 | F23: 0 | G23: 2 | H23: 0 | I23: 2 | J23: 0 | K23: 0 | L23: 8 | N23: Sum of Lượt khám Tiểu học | O23: Column Labels
A24: Mắt | B24: Viêm kết mạc mắt | C24: 1 | D24: 1 | E24: 0 | F24: 0 | G24: 2 | H24: 1 | I24: 1 | J24: 0 | K24: 0 | L24: 8 | N24: Row Labels | O24: 9 | P24: Grand Total
A25: Răng hàm mặt | B25: Đau răng | C25: 0 | D25: 1 | E25: 2 | F25: 1 | G25: 5 | H25: 0 | I25: 1 | J25: 3 | K25: 1 | L25: 8 | N25: Bệnh truyền nhiễm | O25: 53 | P25: 53
A26: Răng hàm mặt | B26: Rụng răng sữa | C26: 0 | D26: 6 | E26: 2 | F26: 0 | G26: 8 | H26: 0 | I26: 6 | J26: 2 | K26: 0 | L26: 8 | N26: Bỏng da | O26: 1 | P26: 1
A27: Răng hàm mặt | B27: Viêm loét niêm mạc miệng (nhiệt miệng) | C27: 0 | D27: 3 | E27: 1 | F27: 0 | G27: 4 | H27: 0 | I27: 3 | J27: 1 | K27: 0 | L27: 8 | N27: Chấn thương | O27: 34 | P27: 34
A28: Răng hàm mặt | B28: Dập môi | C28: 0 | D28: 1 | E28: 1 | F28: 0 | G28: 2 | H28: 0 | I28: 1 | J28: 1 | K28: 0 | L28: 8 | N28: Da liễu | O28: 11 | P28: 11
A29: Răng hàm mặt | B29: Rớt mắc cài niềng răng | C29: 0 | D29: 0 | E29: 1 | F29: 0 | G29: 1 | H29: 0 | I29: 0 | J29: 1 | K29: 0 | L29: 8 | N29: Hô hấp | O29: 7 | P29: 7
A30: Răng hàm mặt | B30: Viêm nướu | C30: 0 | D30: 1 | E30: 0 | F30: 0 | G30: 1 | H30: 0 | I30: 1 | J30: 0 | K30: 0 | L30: 8 | N30: Mắt | O30: 28 | P30: 28
A31: Tai mũi họng | B31: Viêm họng | C31: 4 | D31: 46 | E31: 70 | F31: 16 | G31: 174 | H31: 4 | I31: 54 | J31: 98 | K31: 18 | L31: 8 | N31: Răng hàm mặt | O31: 11 | P31: 11
A32: Tai mũi họng | B32: Viêm mũi dị ứng | C32: 1 | D32: 0 | E32: 2 | F32: 5 | G32: 9 | H32: 1 | I32: 0 | J32: 2 | K32: 6 | L32: 8 | N32: Tai mũi họng | O32: 84 | P32: 84
A33: Tai mũi họng | B33: Viêm xoang | C33: 0 | D33: 0 | E33: 0 | F33: 1 | G33: 1 | H33: 0 | I33: 0 | J33: 0 | K33: 1 | L33: 8 | N33: Thận - Tiết niệu | O33: 0 | P33: 0
A34: Tai mũi họng | B34: Chảy máu cam | C34: 1 | D34: 21 | E34: 9 | F34: 0 | G34: 37 | H34: 1 | I34: 21 | J34: 15 | K34: 0 | L34: 8 | N34: Tiêu hoá | O34: 24 | P34: 24
A35: Tai mũi họng | B35: Đau tai | C35: 0 | D35: 4 | E35: 1 | F35: 0 | G35: 5 | H35: 0 | I35: 4 | J35: 1 | K35: 0 | L35: 8 | N35: Tim mạch | O35: 0 | P35: 0
A36: Tai mũi họng | B36: Viêm mũi | C36: 0 | D36: 3 | E36: 1 | F36: 0 | G36: 4 | H36: 0 | I36: 3 | J36: 1 | K36: 0 | L36: 8 | N36: Tổng hợp | O36: 135 | P36: 135
... A38: Tai mũi họng | B38: TD Viêm tai giữa | C38: 0 | D38: 1 | E38: 0 | F38: 0 | G38: 1 | H38: 0 | I38: 1 | J38: 0 | K38: 0 | L38: 8 | N38: Grand Total | O38: 454 | P38: 454
A39: Tai mũi họng | B39: Dị vật tai | C39: 0 | D39: 1 | E39: 0 | F39: 0 | G39: 1 | H39: 0 | I39: 1 | J39: 0 | K39: 0 | L39: 8
A40: Thần Kinh | B40: Rối loạn tiền đình | C40: 0 | D40: 0 | E40: 1 | F40: 0 | G40: 1 | H40: 0 | I40: 0 | J40: 1 | K40: 0 | L40: 8
A41: Tiêu hoá | B41: Rối loạn tiêu hoá | C41: 3 | D41: 27 | E41: 19 | F41: 9 | G41: 62 | H41: 3 | I41: 31 | J41: 19 | K41: 9 | L41: 8 | N41: Sum of Lượt khám THCS | O41: Column Labels
A42: Tiêu hoá | B42: Viêm dạ dày | C42: 0 | D42: 3 | E42: 5 | F42: 7 | G42: 16 | H42: 0 | I42: 4 | J42: 5 | K42: 7 | L42: 8 | N42: Row Labels | O42: 9 | P42: Grand Total
...

Sheet 5. Nghỉ phép
A1: MaNV | B1: HoTen | C1: PhongBan | D1: TenChiTiet | E1: GhiChu | F1: SoNgayThang | G1: TuNgayT | H1: DenNgayT | I1: Tháng | J1: Buoi | L1: PhongBan | M1: (All) | O1: Tháng | P1: 9
A2: NV0001104 | B2: Bùi Thị Bích Trâm | D2: Nghỉ phép năm | E2: Nhân sự giải quyết phép năm tồn | F2: 1 | G2: 31/08/2026 | H2: 31/08/2026 | I2: 8
A3: NV0000080 | B3: Hoàng Văn Thanh | C3: Phòng Quản trị - An toàn và môi trường | D3: Nghỉ phép năm | F3: 0.5 | G3: 29/08/2026 | H3: 29/08/2026 | I3: 8 | J3: Sáng | L3: Row Labels | M3: Sum of SoNgayThang | O3: Row Labels | P3: Sum of SoNgayThang
A4: NV0000108 | B4: Hà Thị Kim Sang | C4: Bộ Phận Bếp | D4: Nghỉ khám bệnh trong 1 học kỳ | F4: 0.5 | G4: 29/08/2026 | H4: 29/08/2026 | I4: 8 | J4: Sáng | L4: Bản thân kết hôn | M4: 1 | O4: ABDUL MAJID MARANI SWALLAH | P4: 15 | Q4: Điều trị ung thư
A5: NV0000242 | B5: Trần Thanh Bền | C5: Phòng Quản trị - An toàn và môi trường | D5: Nghỉ phép năm | F5: 0.5 | G5: 29/08/2026 | H5: 29/08/2026 | I5: 8 | J5: Chiều | L5: Khám thai định kỳ (5 ngày/1 chu kỳ) | M5: 6 | O5: Hoàng Thị Diễm Trang | P5: 8 | Q5: =VLOOKUP(O5,B:E,4,0) -> Làm việc tại nhà.
A6: NV0001199 | B6: Carreon Gugol Vanessa Ariane | C6: Tổ Ngoại Ngữ, Khối THCS -THPT | D6: Nghỉ khám bệnh trong 1 học kỳ | F6: 1 | G6: 28/08/2026 | H6: 28/08/2026 | I6: 8 | L6: Nghỉ khám bệnh trong 1 học kỳ | M6: 32 | O6: Huỳnh Thanh Trí | P6: 10 | Q6: Nhân viên bếp mổ sỏi thận
A7: NV0000145 | B7: Trần Thị Thùy Trang | C7: Khối Mầm Non | D7: Nghỉ phép năm | E7: Ứng phép của nảm 26-27 | F7: 0.5 | G7: 28/08/2026 | H7: 28/08/2026 | I7: 8 | J7: Sáng | L7: Nghỉ không lương -Có BHXH | M7: 52.5 | O7: Khương Anh Tuấn | P7: 8.5 | Q7: =VLOOKUP(O7,B:E,4,0) -> Số hóa văn bằng, chứng chỉ tại Sở Giáo Dục TP. Đồng Nai
A8: NV0000197 | B8: Trần Thị Thanh Thủy | C8: Bộ phận Nhân sự | D8: Nghỉ phép năm | E8: Chăm má sau phẫu thuật | F8: 1 | G8: 28/08/2026 | H8: 28/08/2026 | I8: 8 | L8: Nghỉ không lương -Không BHXH | M8: 15 | O8: Khương Thị Ngọc Phụng | P8: 5 | Q8: =VLOOKUP(O8,B:E,4,0) -> Nhà có tang
A9: NV0000368 | B9: Nguyễn Thị Kim Liên | C9: Bộ phận Thư viện, Khối THCS -THPT | D9: Nghỉ phép năm | F9: 0.5 | G9: 28/08/2026 | H9: 28/08/2026 | I9: 8 | J9: Chiều | L9: Nghỉ ốm (1 ngày/1 quý) | M9: 4 | O9: Lê Bá Quang Thắng | P9: 10.5 | Q9: Thực hiện nghĩa vụ quân sự
A10: NV0000379 | B10: Dương Thị Gọn | C10: Bộ Phận Bếp | D10: Nghỉ không lương -Không BHXH | E10: NS | F10: 1 | G10: 28/08/2026 | H10: 28/08/2026 | I10: 8 | L10: Nghỉ phép năm | M10: 105.5 | O10: Nguyễn Duy Thanh Thảo | P10: 5 | Q10: Chồng mất, có tang chế
A11: NV0000928 | B11: Ngô Thị Xuân Thủy | C11: Khối Mầm Non, Bộ Phận Bếp | D11: Nghỉ khám bệnh trong 1 học kỳ | E11: NS | F11: 1 | G11: 28/08/2026 | H11: 28/08/2026 | I11: 8 | L11: Nghỉ thai sản - Hưởng BHXH | M11: 6 | O11: Nguyễn Ngọc Mai Anh | P11: 6 | Q11: =VLOOKUP(O11,B:E,4,0) -> Nghỉ nửa ngày buổi chiều ngày 14/08 phép học kỳ
A12: NV0000902 | B12: Dalumpines Obregon Kizzle Kaye | C12: Tổ Ngoại Ngữ, Khối Tiểu Học | D12: Nghỉ không lương -Không BHXH | F12: 1 | G12: 28/08/2026 | H12: 28/08/2026 | I12: 8 | L12: Tập huấn. công tác | M12: 50 | O12: Nguyễn Thị Hồng Vân | P12: 16 | Q12: Nghỉ
A13: NV0001272 | B13: Đỗ Thị Thanh | C13: Đơn vị Long Khánh | D13: Nghỉ phép năm | F13: 1 | G13: 28/08/2026 | H13: 28/08/2026 | I13: 8 | L13: Tứ thân phụ mẫu, vợ (chồng), con: mất | M13: 17 | O13: Nguyễn Thị Nga | P13: 5 | Q13: =VLOOKUP(O13,B:E,4,0) -> Chăm con nhỏ bị ốm.
A14: NV0000902 | B14: Dalumpines Obregon Kizzle Kaye | C14: Tổ Ngoại Ngữ, Khối Tiểu Học | D14: Nghỉ khám bệnh trong 1 học kỳ | F14: 1 | G14: 27/08/2026 | H14: 27/08/2026 | I14: 8 | L14: Grand Total | M14: 289 | O14: Nguyễn Thị Thanh Tâm | P14: 5 | Q14: Mẹ mất, nhà có tang chế
A15: NV0001089 | B15: Nguyễn Trần Gia Hân | C15: Tổ Ngoại Ngữ, Khối THCS -THPT | D15: Nghỉ khám bệnh trong 1 học kỳ | E15: Đi khám răng | F15: 0.5 | G15: 27/08/2026 | H15: 27/08/2026 | I15: 8 | J15: Chiều | O15: Trần Thanh Hiền | P15: 8 | Q15: =VLOOKUP(O15,B:E,4,0) -> Nghỉ khám thai ở phòng khám tư nên không có giấy nghỉ.
A16: NV0000122 | B16: Phan Thị Ngọc Nga | C16: Hành chính chuyên môn | D16: Nghỉ phép năm | F16: 0.5 | G16: 27/08/2026 | H16: 27/08/2026 | I16: 8 | J16: Chiều | O16: Trương Thu Trang | P16: 8 | Q16: =VLOOKUP(O16,B:E,4,0) -> Chăm con nằm viện
A17: NV0001374 | B17: Nguyễn Vũ Kim Ngân | C17: Khối Mầm Non | D17: Nghỉ khám bệnh trong 1 học kỳ | F17: 1 | G17: 27/08/2026 | H17: 27/08/2026 | I17: 8 | O17: Grand Total | P17: 110
A18: NV0001073 | B18: Nguyễn Đình Hạnh | C18: Marketing - TVTS - CSKH | D18: Nghỉ phép năm | E18: Đăng kí nghỉ phép cả ngày 27/8/2026 | F18: 1 | G18: 27/08/2026 | H18: 27/08/2026 | I18: 8
A19: NV0001287 | B19: Lê Bá Quang Thắng | C19: Marketing - TVTS - CSKH | D19: Nghỉ phép năm | F19: 1 | G19: 27/08/2026 | H19: 27/08/2026 | I19: 8
A20: NV0000012 | B20: Nguyễn Thị Hằng | D20: Nghỉ phép năm | E20: Nhân sự giải quyết phép nghỉ việc T7&T8/2026 | F20: 2 | G20: 27/08/2026 | H20: 28/08/2026 | I20: 8
A21: NV0000924 | B21: Mai Thị Kim Ngân | C21: Hành chính chuyên môn | D21: Nghỉ phép năm | F21: 0.5 | G21: 27/08/2026 | H21: 27/08/2026 | I21: 8 | J21: Sáng
A22: NV0000792 | B22: Trần Thị Hoa | C22: Ban Giám Đốc | D22: Nghỉ phép năm | E22: Làm việc tại nhà | F22: 1 | G22: 27/08/2026 | H22: 27/08/2026 | I22: 8
A23: NV0000226 | B23: Nguyễn Thị Diễm Trang | C23: Khối Mầm Non | D23: Nghỉ phép năm | F23: 0.5 | G23: 27/08/2026 | H23: 27/08/2026 | I23: 8 | J23: Chiều
A24: NV0001306 | B24: Hoàng Thị Diễm Trang | C24: Ban Giám Hiệu | D24: Tập huấn. công tác | E24: Làm việc tại nhà. | F24: 1 | G24: 27/08/2026 | H24: 27/08/2026 | I24: 8
A25: NV0000904 | B25: Lopez Anne Julia Redor | C25: Tổ Ngoại Ngữ, Khối THCS -THPT | D25: Nghỉ ốm (1 ngày/1 quý) | F25: 0.5 | G25: 27/08/2026 | H25: 27/08/2026 | I25: 8 | J25: Chiều
A26: NV0001396 | B26: Trần Thị Thanh Tâm | D26: Nghỉ không lương -Không BHXH | F26: 2 | G26: 27/08/2026 | H26: 28/08/2026 | I26: 8
A27: NV0001292 | B27: Võ Kim Ngân | C27: Khối Mầm Non | D27: Nghỉ không lương -Có BHXH | F27: 1 | G27: 27/08/2026 | H27: 27/08/2026 | I27: 8
A28: NV0000337 | B28: Trần Thị Như Vy | C28: Khối Tiểu Học | D28: Nghỉ phép năm | F28: 0.5 | G28: 27/08/2026 | H28: 27/08/2026 | I28: 8 | J28: Sáng
A29: NV0000197 | B29: Trần Thị Thanh Thủy | C29: Bộ phận Nhân sự | D29: Nghỉ phép năm | E29: Bận việc gđ | F29: 1 | G29: 27/08/2026 | H29: 27/08/2026 | I29: 8
A30: NV0000037 | B30: Phạm Thị Linh | C30: Tổ xã hội, Khối THCS -THPT | D30: Tập huấn. công tác | E30: Tập huấn lý luận chính trị hè năm 2026 | F30: 2 | G30: 27/08/2026 | H30: 28/08/2026 | I30: 8
A31: NV0000069 | B31: Võ Thị Hồng Nhung | C31: Dịch vụ học sinh | D31: Nghỉ phép năm | F31: 1 | G31: 27/08/2026 | H31: 27/08/2026 | I31: 8
A32: NV0001390 | B32: Nguyễn Thị Thanh Thuỷ | C32: Đơn vị Long Khánh | D32: Nghỉ phép năm | F32: 0.5 | G32: 27/08/2026 | H32: 27/08/2026 | I32: 8 | J32: Sáng
A33: NV0000009 | B33: Trương Thu Trang | C33: Ban Giám Hiệu | D33: Nghỉ phép năm | E33: Chăm con nằm viện | F33: 2 | G33: 26/08/2026 | H33: 27/08/2026 | I33: 8
A34: NV0000976 | B34: Nguyễn Thị Kim Phượng | C34: Khối Mầm Non | D34: Nghỉ khám bệnh trong 1 học kỳ | F34: 0.5 | G34: 26/08/2026 | H34: 26/08/2026 | I34: 8 | J34: Sáng
A35: NV0000659 | B35: Nguyễn Thị Bích Huyền | C35: Đơn vị Long Khánh | D35: Nghỉ phép năm | F35: 0.5 | G35: 26/08/2026 | H35: 26/08/2026 | I35: 8 | J35: Chiều
A36: NV0000155 | B36: Khương Thị Ngọc Phụng | C36: Dịch vụ học sinh | D36: Tứ thân phụ mẫu, vợ (chồng), con: mất | E36: Nhà có tang | F36: 3 | G36: 26/08/2026 | H36: 28/08/2026 | I36: 8
A37: NV0000382 | B37: Trịnh Văn Tiến | C37: Khối Mầm Non, Bộ Phận Bếp | D37: Nghỉ phép năm | F37: 1 | G37: 26/08/2026 | H37: 26/08/2026 | I37: 8
A38: NV0001287 | B38: Lê Bá Quang Thắng | C38: Marketing - TVTS - CSKH | D38: Nghỉ phép năm | F38: 0.5 | G38: 26/08/2026 | H38: 26/08/2026 | I38: 8 | J38: Chiều
A39: NV0001150 | B39: Nguyễn Thị Thuý Hằng | C39: Dịch vụ học sinh | D39: Nghỉ phép năm | F39: 0.5 | G39: 26/08/2026 | H39: 26/08/2026 | I39: 8 | J39: Chiều
A40: NV0000712 | B40: ABDUL MAJID MARANI SWALLAH | C40: Tổ Ngoại Ngữ, Khối Tiểu Học | D40: Nghỉ không lương -Có BHXH | F40: 3 | G40: 26/08/2026 | H40: 28/08/2026 | I40: 8
...

Sheet 6. Sửa chữa
A1: Thống kê danh mục theo tháng
A2: Column1 | B2: 6/2026 | C2: 7/2026 | D2: 8/2026 | E2: 9/2026 | F2: 10/2026 | G2: 11/2026 | H2: 12/2026 | I2: 1/2027 | J2: 2/2027 | K2: 3/2027 | L2: 4/2027 | M2: 5/2027 | N2: Tổng cộng
A3: Máy lạnh | B3: 5 | C3: 9 | D3: 23 | E3: 18 | F3: 0 | G3: 0 | H3: 0 | I3: 0 | J3: 0 | K3: 0 | L3: 0 | M3: 0 | N3: 41
A4: Máy PC | B4: 1 | C4: 7 | D4: 7 | E4: 9 | F4: 0 | G4: 0 | H4: 0 | J4: 0 | K4: 0 | L4: 0 | M4: 0 | N4: 17
A5: Tivi | B5: 1 | C5: 1 | D5: 13 | E5: 8 | F5: 0 | G5: 0 | H5: 0 | I5: 0 | J5: 0 | K5: 0 | L5: 0 | M5: 0 | N5: 17
A6: Quạt xoay | B6: 0 | C6: 2 | D6: 9 | E6: 7 | F6: 0 | G6: 0 | H6: 0 | I6: 0 | J6: 0 | K6: 0 | L6: 0 | M6: 0 | N6: 12
A7: Bảng | B7: 0 | C7: 4 | D7: 7 | E7: 3 | F7: 0 | G7: 0 | H7: 0 | I7: 0 | J7: 0 | K7: 0 | L7: 0 | M7: 0 | N7: 11
A8: Rèm vải cuốn | B8: 0 | C8: 0 | D8: 6 | E8: 5 | F8: 0 | G8: 0 | H8: 0 | I8: 0 | J8: 0 | K8: 0 | L8: 0 | M8: 0 | N8: 10
A9: Remote TV | B9: 0 | C9: 4 | D9: 4 | E9: 2 | F9: 0 | G9: 0 | H9: 0 | I9: 0 | J9: 0 | K9: 0 | L9: 0 | M9: 0 | N9: 8
A10: Đồng hồ treo | B10: 1 | C10: 3 | D10: 3 | E10: 3 | F10: 0 | G10: 0 | H10: 0 | I10: 0 | J10: 0 | K10: 0 | L10: 0 | M10: 0 | N10: 7
A11: Ghế MOTO6 xám | B11: 0 | C11: 0 | D11: 6 | E11: 4 | F11: 0 | G11: 0 | H11: 0 | I11: 0 | J11: 0 | K11: 0 | L11: 0 | M11: 0 | N11: 7
A12: Tủ gỗ GV | B12: 0 | C12: 5 | D12: 1 | E12: 0 | F12: 0 | G12: 0 | H12: 0 | I12: 0 | J12: 0 | K12: 0 | L12: 0 | M12: 0 | N12: 6
A13: Khác | B13: 13 | C13: 13 | D13: 31 | E13: 20 | F13: 0 | G13: 0 | H13: 0 | I13: 0 | J13: 0 | K13: 0 | L13: 0 | M13: 0 | N13: 59
B14: =SUBTOTAL(109,Table1[6/2026]) -> 21 | C14: =SUBTOTAL(109,Table1[7/2026]) -> 48 | D14: =SUBTOTAL(109,Table1[8/2026]) -> 110 | E14: =SUBTOTAL(109,Table1[9/2026]) -> 79 | F14: =SUBTOTAL(109,Table1[10/2026]) -> 0 | G14: =SUBTOTAL(109,Table1[11/2026]) -> 0 | H14: =SUBTOTAL(109,Table1[12/2026]) -> 0 | I14: =SUBTOTAL(109,Table1[1/2027]) -> 0 | J14: =SUBTOTAL(109,Table1[2/2027]) -> 0 | K14: =SUBTOTAL(109,Table1[3/2027]) -> 0 | L14: =SUBTOTAL(109,Table1[4/2027]) -> 0 | M14: =SUBTOTAL(109,Table1[5/2027]) -> 0 | N14: =SUBTOTAL(109,Table1[Tổng cộng]) -> 195
A15: Báo sửa trong tháng theo Khu (Top 10)
A16: Column9 | B16: Khu A | C16: Khu B | D16: Khu C | E16: Khu D | F16: Khu E | G16: Cơ sở 2 | H16: Cơ sở Long Khánh | I16: Tổng cộng
A17: Máy lạnh | B17: 1 | C17: 10 | D17: 7 | E17: 0 | F17: 0 | G17: 0 | H17: 0 | I17: 18
A18: Máy PC | B18: 0 | C18: 1 | D18: 0 | E18: 0 | F18: 7 | G18: 0 | H18: 1 | I18: 9
A19: Tivi | B19: 0 | C19: 4 | D19: 4 | E19: 0 | F19: 0 | G19: 0 | H19: 0 | I19: 8
A20: Quạt xoay | B20: 0 | C20: 5 | D20: 2 | E20: 0 | F20: 0 | G20: 0 | H20: 0 | I20: 7
A21: Rèm vải cuốn | B21: 0 | C21: 3 | D21: 2 | E21: 0 | F21: 0 | G21: 0 | H21: 0 | I21: 5
A22: Đèn đôi 1.2m | B22: 0 | C22: 1 | D22: 3 | E22: 0 | F22: 0 | G22: 0 | H22: 0 | I22: 4
A23: Bảng | B23: 0 | C23: 1 | D23: 2 | E23: 0 | F23: 0 | G23: 0 | H23: 0 | I23: 3
A24: Ghế MOTO5 cam | B24: 0 | C24: 0 | D24: 3 | E24: 0 | F24: 0 | G24: 0 | H24: 0 | I24: 3
A25: Ghế MOTO6 xám | B25: 0 | C25: 0 | D25: 3 | E25: 0 | F25: 0 | G25: 0 | H25: 0 | I25: 3
A26: Quạt treo tường | B26: 0 | C26: 2 | D26: 0 | E26: 0 | F26: 0 | G26: 1 | H26: 0 | I26: 3
A28: Thống kê theo nhân viên xử lý
A29: Column2 | B29: Column1 | C29: 6/2026 | D29: 7/2026 | E29: 8/2026 | F29: 9/2026 | G29: 10/2026 | H29: 11/2026 | I29: 12/2026 | J29: 1/2027 | K29: 2/2027 | L29: 3/2027 | M29: 4/2027 | N29: 5/2027 | O29: Tổng cộng
A30: Hoàng Văn Thanh | B30: Phòng Quản trị - An toàn và môi trường | C30: 2 | D30: 19 | E30: 33 | F30: 26 | G30: 2 | H30: 0 | I30: 0 | J30: 0 | K30: 0 | L30: 0 | M30: 0 | N30: 0 | O30: =SUM(Table4[[#This Row],[6/2026]:[5/2027]]) -> 82
A31: Đỗ Anh Hào | B31: Phòng Quản trị - An toàn và môi trường | C31: 6 | D31: 30 | E31: 30 | F31: 14 | G31: 1 | H31: 0 | I31: 0 | J31: 0 | K31: 0 | L31: 0 | M31: 0 | N31: 0 | O31: =SUM(Table4[[#This Row],[6/2026]:[5/2027]]) -> 81
A32: Trần Thanh Bền | B32: Phòng Quản trị - An toàn và môi trường | C32: 4 | D32: 6 | E32: 30 | F32: 22 | G32: 3 | H32: 0 | I32: 0 | J32: 0 | K32: 0 | L32: 0 | M32: 0 | N32: 0 | O32: =SUM(Table4[[#This Row],[6/2026]:[5/2027]]) -> 65
A33: Tống Anh Kha | B33: Phòng IT | C33: 0 | D33: 3 | E33: 11 | F33: 5 | G33: 1 | H33: 0 | I33: 0 | J33: 0 | K33: 0 | L33: 0 | M33: 0 | N33: 0 | O33: =SUM(Table4[[#This Row],[6/2026]:[5/2027]]) -> 20
A34: Trần Mai Minh Trí | B34: Phòng IT | C34: 1 | D34: 2 | E34: 1 | F34: 15 | G34: 0 | H34: 0 | I34: 0 | J34: 0 | K34: 0 | L34: 0 | M34: 0 | N34: 0 | O34: =SUM(Table4[[#This Row],[6/2026]:[5/2027]]) -> 19
A35: Mai Thanh Phương | B35: Phòng IT | C35: 6 | D35: 3 | E35: 2 | F35: 1 | G35: 0 | H35: 0 | I35: 0 | J35: 0 | K35: 0 | L35: 0 | M35: 0 | N35: 0 | O35: =SUM(Table4[[#This Row],[6/2026]:[5/2027]]) -> 12
A36: Nguyễn Ngọc Thuận | B36: Đơn vị Long Khánh | C36: 3 | D36: 2 | E36: 3 | F36: 2 | G36: 0 | H36: 0 | I36: 0 | J36: 0 | K36: 0 | L36: 0 | M36: 0 | N36: 0 | O36: =SUM(Table4[[#This Row],[6/2026]:[5/2027]]) -> 10
A37: Lương Văn Tuấn | B37: Phòng IT | C37: 0 | D37: 1 | E37: 8 | F37: 1 | G37: 0 | H37: 0 | I37: 0 | J37: 0 | K37: 0 | L37: 0 | M37: 0 | N37: 0 | O37: =SUM(Table4[[#This Row],[6/2026]:[5/2027]]) -> 10
A38: Dương Thái Nguyên | B38: Phòng IT | C38: 1 | D38: 3 | E38: 4 | F38: 1 | G38: 0 | H38: 0 | I38: 0 | J38: 0 | K38: 0 | L38: 0 | M38: 0 | N38: 0 | O38: =SUM(Table4[[#This Row],[6/2026]:[5/2027]]) -> 9
A39: Bùi Đặng Quốc Khánh | B39: Phòng IT | C39: 0 | D39: 0 | E39: 5 | F39: 2 | G39: 1 | H39: 0 | I39: 0 | J39: 0 | K39: 0 | L39: 0 | M39: 0 | N39: 0 | O39: =SUM(Table4[[#This Row],[6/2026]:[5/2027]]) -> 8
A40: Hồ Văn Minh | B40: Phòng IT | C40: 0 | D40: 0 | E40: 4 | F40: 1 | G40: 1 | H40: 0 | I40: 0 | J40: 0 | K40: 0 | L40: 0 | M40: 0 | N40: 0 | O40: =SUM(Table4[[#This Row],[6/2026]:[5/2027]]) -> 6
A41: Phạm Đình Thịnh | B41: Phòng IT | C41: 3 | D41: 1 | E41: 0 | F41: 0 | G41: 0 | H41: 0 | I41: 0 | J41: 0 | K41: 0 | L41: 0 | M41: 0 | N41: 0 | O41: =SUM(Table4[[#This Row],[6/2026]:[5/2027]]) -> 4
...

Sheet 7. Biến động nhân sự
A1: STT | B1: Mã NV | C1: Họ | D1: Tên | E1: Tình trạng | F1: Phòng ban | G1: Chức vụ | H1: Giới tính | I1: Ngày HĐ | J1: Loại HĐ | K1: Ngày hiệu lực HĐ | L1: Ghi chú | M1: Tháng | N1: Năm
A2: 1 | B2: NV0001062 | C2: Nguyễn Hoàng | D2: Nam | E2: Lao động vào làm trong tháng | F2: Khối Mầm Non | G2: Giáo viên | H2: Nam | I2: 01/08/2026 | J2: Hợp đồng chính thức có xác định thời hạn 1 năm | K2: 01/08/2026 | L2: Tăng | M2: 8 | N2: 2026
A3: 2 | B3: NV0001383 | C3: Đinh Minh | D3: Đức | E3: Lao động vào làm trong tháng | F3: Khối Mầm Non | G3: Trợ Giảng | H3: Nam | I3: 03/08/2026 | J3: Hợp đồng thỉnh giảng | K3: 03/08/2026 | L3: Tăng | M3: 8 | N3: 2026
A4: 3 | B4: NV0001384 | C4: Nguyễn Đặng Khánh | D4: Vy | E4: Lao động vào làm trong tháng | F4: Khối Mầm Non | G4: Trợ Giảng | H4: Nữ | I4: 03/08/2026 | J4: Hợp đồng thỉnh giảng | K4: 03/08/2026 | L4: Tăng | M4: 8 | N4: 2026
A5: 4 | B5: NV0001425 | C5: Hồ Thị Kim | D5: Liên | E5: Lao động vào làm trong tháng | F5: Khối Mầm Non | G5: Phó hiệu trưởng | H5: Nữ | I5: 24/08/2026 | J5: Hợp đồng thử việc | K5: 24/08/2026 | L5: Tăng | M5: 8 | N5: 2026
A6: 5 | B6: NV0001426 | C6: Nguyễn Cao Mỹ | D6: Phụng | E6: Lao động vào làm trong tháng | F6: Tổ Quản Sinh | G6: Nhân viên | H6: Nữ | I6: 01/08/2026 | J6: Hợp đồng khoán công việc | K6: 01/08/2026 | L6: Tăng | M6: 8 | N6: 2026
A7: 6 | B7: NV0001427 | C7: Nguyễn Hoàng Như | D7: Ngọc | E7: Lao động vào làm trong tháng | F7: Tổ Hoạt động trải nghiệm, hướng nghiệp | G7: Nhân viên Tham vấn học đường | H7: Nữ | I7: 10/08/2026 | J7: Hợp đồng thử việc | K7: 10/08/2026 | L7: Tăng | M7: 8 | N7: 2026
A8: 7 | B8: NV0001430 | C8: Trần Thị Hồng | D8: Thắm | E8: Lao động vào làm trong tháng | F8: Đơn vị Long Khánh | G8: Giáo viên | H8: Nữ | I8: 03/08/2026 | J8: Hợp đồng thử việc | K8: 03/08/2026 | L8: Tăng | M8: 8 | N8: 2026
A9: 8 | B9: NV0001431 | C9: Vũ Thị | D9: Ngọc | E9: Lao động vào làm trong tháng | F9: Khối Mầm Non | G9: Giáo viên | H9: Nữ | I9: 17/08/2026 | J9: Hợp đồng thử việc | K9: 17/08/2026 | L9: Tăng | M9: 8 | N9: 2026
A10: 9 | B10: NV0001433 | C10: MUEGNA REPONTE | D10: KRISTY JANE | E10: Lao động vào làm trong tháng | F10: Tổ Ngoại Ngữ | G10: Giáo viên | H10: Nữ | I10: 17/08/2026 | J10: Hợp đồng thử việc | K10: 17/08/2026 | L10: Tăng | M10: 8 | N10: 2026
A11: 10 | B11: NV0001434 | C11: Đặng Minh | D11: Hải | E11: Lao động vào làm trong tháng | F11: Bộ Phận Bếp | G11: Nhân viên | H11: Nam | I11: 10/08/2026 | J11: Hợp đồng chính thức có xác định thời hạn 1 năm | K11: 10/08/2026 | L11: Tăng | M11: 8 | N11: 2026
A12: 11 | B12: NV0001435 | C12: Nguyễn Việt | D12: Hiếu | E12: Lao động vào làm trong tháng | F12: Tổ thể dục - Quốc phòng - Nghệ thuật | G12: Giáo viên | H12: Nam | I12: 17/08/2026 | J12: Hợp đồng thỉnh giảng | K12: 17/08/2026 | L12: Tăng | M12: 8 | N12: 2026
A13: 12 | B13: NV0000012 | C13: Nguyễn Thị | D13: Hằng | E13: Lao động nghỉ làm trong tháng | F13: Khối Tiểu Học | G13: Trợ Giảng | H13: Nữ | I13: 04/05/2023 | J13: Hợp đồng chính thức không xác định thời hạn | K13: 04/05/2023 | L13: Giảm | M13: 8 | N13: 2026
... A18: 3 | B18: NV0001436 | C18: Nguyễn Thị Kiều | D18: Duyên | E18: Lao động vào làm trong tháng | F18: Khối Tiểu Học | G18: Trợ Giảng | H18: Nữ | I18: 03/09/2026 | J18: Hợp đồng thử việc | K18: 03/09/2026 | L18: Tăng | M18: 9 | N18: 2026
